Workbook

Sheet 2024
A1: OFICINA | B1: MES | C1: FACTURA | D1: TRAFICO | E1: FECHA | F1: CLIENTE | G1: CLIENTENOMBRE | H1: IMPORTE | K1: Total Facturado
A2: NLD | B2: Marzo | C2: 2-001265 | D2: CGL24011266 | E2: 45357 | F2: C0051 | G2: NAPS-GUANAJUATO NORTWHIRE | H2: 3432.66
A3: NLD | B3: Marzo | C3: 2-001273 | D3: CGL24021361 | E3: 45357 | F3: C0003 | G3: NAPS-GUANAJUATO WARREN | H3: 3235
A4: NLD | B4: Marzo | C4: 2-001271 | D4: CGL24011292 | E4: 45357 | F4: C0003 | G4: NAPS-GUANAJUATO WARREN | H4: 3235
A5: NLD | B5: Marzo | C5: 2-001269 | D5: CGL24021376 | E5: 45357 | F5: C0002 | G5: NAPS-GUANAJUATO CAM | H5: 11471.1
A6: NLD | B6: Marzo | C6: 2-001272 | D6: CGL24011291 | E6: 45357 | F6: C0003 | G6: NAPS-GUANAJUATO WARREN | H6: 11705
A7: NLD | B7: Marzo | C7: 2-001268 | D7: CGL24011264 | E7: 45357 | F7: C0002 | G7: NAPS-GUANAJUATO CAM | H7: 1500
A8: VER | B8: Marzo | C8: 1-001270 | D8: CGL24011315 | E8: 45357 | F8: C0003 | G8: NAPS-GUANAJUATO WARREN | H8: 2040
A9: NLD | B9: Marzo | C9: 2-001267 | D9: CGL24021385 | E9: 45357 | F9: C0051 | G9: NAPS-GUANAJUATO NORTWHIRE | H9: 3412.04 | K9: ABRIL | L9: =SUM(H155:H264) -> 2905974.9 | M9: =+H253 -> 41047.588 | N9: =+L9-M9 -> 2864927.4
A10: NLD | B10: Marzo | C10: 2-001274 | D10: CGL24011224 | E10: 45357 | F10: C0003 | G10: NAPS-GUANAJUATO WARREN | H10: 3235
A11: NLD | B11: Marzo | C11: 2-001316 | D11: CGL23111119 | E11: 45358 | F11: C0003 | G11: NAPS-GUANAJUATO WARREN | H11: 3235
A12: VER | B12: Marzo | C12: 1-001283 | D12: CGL23060632 | E12: 45358 | F12: C0003 | G12: NAPS-GUANAJUATO WARREN | H12: 58886
A13: NLD | B13: Marzo | C13: 2-001306 | D13: CGL23111093 | E13: 45358 | F13: C0003 | G13: NAPS-GUANAJUATO WARREN | H13: 3235
A14: NLD | B14: Marzo | C14: 2-001311 | D14: CGL23111108 | E14: 45358 | F14: C0003 | G14: NAPS-GUANAJUATO WARREN | H14: 3235
A15: VER | B15: Marzo | C15: 1-001284 | D15: CGL23060632 | E15: 45358 | F15: C0003 | G15: NAPS-GUANAJUATO WARREN | H15: 1285.19
A16: VER | B16: Marzo | C16: 1-001285 | D16: CGL23080841 | E16: 45358 | F16: C0003 | G16: NAPS-GUANAJUATO WARREN | H16: 126298.53
A17: VER | B17: Marzo | C17: 1-001285 | D17: CGL23080841 | E17: 45358 | F17: C0003 | G17: NAPS-GUANAJUATO WARREN | H17: 3553.67
A18: NLD | B18: Marzo | C18: 2-001328 | D18: CGL24021353 | E18: 45358 | F18: C0003 | G18: NAPS-GUANAJUATO WARREN | H18: 2035
A19: VER | B19: Marzo | C19: 1-001308 | D19: CGL23090927 | E19: 45358 | F19: C0003 | G19: NAPS-GUANAJUATO WARREN | H19: 94969
A20: VER | B20: Marzo | C20: 1-001308 | D20: CGL23090927 | E20: 45358 | F20: C0003 | G20: NAPS-GUANAJUATO WARREN | H20: 3553.67
A21: VER | B21: Marzo | C21: 1-001318 | D21: CGL23121217 | E21: 45358 | F21: C0003 | G21: NAPS-GUANAJUATO WARREN | H21: 49040.94
... A151: VER | B151: Marzo | C151: 1-001407 | D151: CGL24021409 | E151: 45381 | F151: C0004 | G151: NAPS-GUANAJUATO AMERICAN BOA | H151: 2950
A152: VER | B152: Marzo | C152: 1-001287 | D152: CGL23080841 | E152: 07/03/2024 | F152: C0003 | G152: NAPS-GUANAJUATO WARREN | H152: 62032.69
A153: VER | B153: Marzo | C153: 1-001366 | D153: CGL24031424 | E153: 21/03/2024 | F153: C0001 | G153: ARMOR MEXICO IMAGING SUPPLIES | H153: 69010.168
A154: QRO | B154: Marzo | C154: 3-001391 | D154: CGL240300001-2024/03 | E154: 26/03/2024 | F154: C0033 | G154: CORE GLOBAL TRADING LLC | H154: 17382.067
A155: NLD | B155: Abril | C155: 2-001421 | D155: CGL24031448 | E155: 01/04/2024 | F155: C0003 | G155: NAPS-GUANAJUATO WARREN | H155: 3235
A156: VER | B156: Abril | C156: 1-001424 | D156: CGL24021339 | E156: 04/04/2024 | F156: C0001 | G156: ARMOR MEXICO IMAGING SUPPLIES | H156: 10848.2
A157: NLD | B157: Abril | C157: 2-001425 | D157: CGL24031495 | E157: 04/04/2024 | F157: C0002 | G157: NAPS-GUANAJUATO CAM | H157: 3450
A158: NLD | B158: Abril | C158: 2-001426 | D158: CGL24031467 | E158: 04/04/2024 | F158: C0002 | G158: NAPS-GUANAJUATO CAM | H158: 3822.95
A159: NLD | B159: Abril | C159: 2-001423 | D159: CGL24031468 | E159: 04/04/2024 | F159: C0002 | G159: NAPS-GUANAJUATO CAM | H159: 2430.49
A160: VER | B160: Abril | C160: 1-001430 | D160: CGL24011309 | E160: 08/04/2024 | F160: C0042 | G160: SISTEMAS ACAO | H160: 5626.42
A161: NLD | B161: Abril | C161: 2-001436 | D161: CGL24021395 | E161: 08/04/2024 | F161: C0002 | G161: NAPS-GUANAJUATO CAM | H161: 3342
A162: NLD | B162: Abril | C162: 2-001433 | D162: CGL24021388 | E162: 08/04/2024 | F162: C0001 | G162: ARMOR MEXICO IMAGING SUPPLIES | H162: 31269.24
A163: NLD | B163: Abril | C163: 2-001434 | D163: CGL24021410 | E163: 08/04/2024 | F163: C0001 | G163: ARMOR MEXICO IMAGING SUPPLIES | H163: 3385.14
... A358: VER | B358: Mayo | C358: 1-001626 | D358: CGL24041548 | E358: 31/05/2024 | F358: C0045 | G358: ALMACENES GENERALES VALENCIA SL | H358: 48023.926

Sheet Acumulado 2025
B6: CORE GLOBAL LOGISTICS MANAGEMENT, S.A. DE C.V.
B7: FACTURACIÓN ACUMULADA DEL 1o DE ENERO AL 31 de Diciembre 2025
B9: NOMBRE DEL CLIENTE | C9: MONTO FACTURADO
B10: JOINT PRODUCTION HONOR | C10: 16223901 | D10: =+C10/$C$46 -> 0.39722573
B11: ARMOR MEXICO IMAGING SUPPLIES | C11: 8188306.4 | D11: =+C11/$C$46 -> 0.20048236
B12: NAPS-GUANAJUATO CAM | C12: 3632180 | D12: =+C12/$C$46 -> 0.088930233
B13: NAPS-GUANAJUATO AMERICAN BOA | C13: 2398937.6 | D13: =+C13/$C$46 -> 0.058735549
B14: JOINT PRODUCTION TECTRAN | C14: 2269734.9 | D14: =+C14/$C$46 -> 0.055572152
B15: JOINT PRODUCTION BLACK SMITH | C15: 2189831.1 | D15: =+C15/$C$46 -> 0.053615787
B16: INVICONT OÜ | C16: 1402774.2 | D16: =+C16/$C$46 -> 0.034345501
B17: CHEMICAL COLOR DE MEXICO | C17: 982463.85 | D17: =+C17/$C$46 -> 0.024054629
B18: MEGALUMINIO SERVICIOS | C18: 634797.74 | D18: =+C18/$C$46 -> 0.015542377
B19: CORE GLOBAL TRANSPORT | C19: 526562.69 | D19: =+C19/$C$46 -> 0.012892352
B20: CORPORATIVO ADUANAL ROBLES | C20: 436050.55 | D20: =+C20/$C$46 -> 0.010676254
B21: TENDENCIA INTERIOR | C21: 396158.42 | D21: =+C21/$C$46 -> 0.0096995361
B22: LOGISTICA DE CARGA MORSAN | C22: 345585.99 | D22: =+C22/$C$46 -> 0.0084613216 | H22: MES | I22: 2023 | J22: 2024 | K22: 2025
B23: MORSAN LOGISTICS | C23: 136441.28 | D23: =+C23/$C$46 -> 0.003340626 | G23: =+I23/$I$35 -> 0.068171614 | H23: Enero | I23: 1590863 | J23: 2042669 | K23: 3784231.7 | L23: =+K23-J23 -> 1741562.6
B24: NEXT LOGISTICS XXI S.L | C24: 106124.52 | D24: =+C24/$C$46 -> 0.0025983511 | G24: =+I24/$I$35 -> 0.021637117 | H24: Febrero | I24: 504927 | J24: 3177087.7 | K24: 2164730.2 | L24: =+K24-J24 -> -1012357.5
B25: CLEVELAND DIE QUERETARO | C25: 101253.11 | D25: =+C25/$C$46 -> 0.0024790794 | G25: =+I25/$I$35 -> 0.08074271 | H25: Marzo | I25: 1884224 | J25: 3214387.7 | K25: 3047553.1 | L25: =+K25-J25 -> -166834.61
B26: ND AUTOMOTIVE SYSTEMS MEXICO | C26: 95811.983 | D26: =+C26/$C$46 -> 0.002345859 | G26: =+I26/$I$35 -> 0.068436567 | H26: Abril | I26: 1597046 | J26: 2864927 | K26: 2048128.9 | L26: =+K26-J26 -> -816798.07
B27: NAPS-GUANAJUATO MULTITECH | C27: 92071.64 | D27: =+C27/$C$46 -> 0.0022542805 | G27: =+I27/$I$35 -> 0.088848975 | H27: Mayo | I27: 2073393 | J27: 5851089 | K27: 4644481.3 | L27: =+K27-J27 -> -1206607.6
B28: SELLOS Y RETENES DE SAN LUIS | C28: 84750.13 | D28: =+C28/$C$46 -> 0.0020750208 | G28: =+I28/$I$35 -> 0.11081481 | H28: Junio | I28: 2585991 | J28: =5573113.96-43702.63 -> 5529411.3 | K28: 2520651.7 | L28: =+K28-J28 -> -3008759.7
B29: SUPER POPULAR LOGISTICS | C29: 79946.26 | D29: =+C29/$C$46 -> 0.0019574029 | G29: =+I29/$I$35 -> 0.038918416 | H29: Julio | I29: 908206 | J29: 4235739 | K29: 6323157.8 | L29: =+K29-J29 -> 2087418.8
B30: INTERIORISMO CORP | C30: 75686.926 | D30: =+C30/$C$46 -> 0.0018531174 | G30: =+I30/$I$35 -> 0.099894713 | H30: Agosto | I30: 2331158 | J30: 4006539.8 | K30: 3813293 | L30: =+K30-J30 -> -193246.79
B31: GSI FABRIL | C31: 73429.86 | D31: =+C31/$C$46 -> 0.0017978555 | G31: =+I31/$I$35 -> 0.096064861 | H31: Septiembre | I31: 2241784 | J31: 3083967.9 | K31: 1777591.6 | L31: =+K31-J31 -> -1306376.3
B32: HAHN AUTOMATION | C32: 71882.62 | D32: =+C32/$C$46 -> 0.0017599729 | G32: =+I32/$I$35 -> 0.1208501 | H32: Octubre | I32: 2820176 | J32: 1800526.9 | K32: 2916241.6 | L32: =+K32-J32 -> 1115714.7
B33: LOGISTICA MEXICANA PALCO | C33: 68579.17 | D33: =+C33/$C$46 -> 0.0016790912 | G33: =+I33/$I$35 -> 0.097049942 | H33: Noviembre | I33: 2264772 | J33: 4477784.2 | K33: 3993126.2 | L33: =+K33-J33 -> -484657.98
B34: JOINT PRODUCTION BOOTH | C34: 60956.42 | D34: =+C34/$C$46 -> 0.001492456 | G34: =+I34/$I$35 -> 0.10857018 | H34: Diciembre | I34: 2533610 | J34: 3838396.7 | K34: 3809839.1 | L34: =+K34-J34 -> -28557.582
B35: GOMSA INTEGRADORA | C35: 43985.001 | D35: =+C35/$C$46 -> 0.001076928 | H35: TOTAL | I35: =+SUM(I23:I34) -> 23336150 | J35: =+SUM(J23:J34) -> 44122526 | K35: =+SUM(K23:K34) -> 40843026 | L35: =+K35-J35 -> -3279500
B36: NAPS-JUAREZ | C36: 42239.67 | D36: =+C36/$C$46 -> 0.0010341954
B37: JOINT PRODUCTION (HCMF) | C37: 29254.9 | D37: =+C37/$C$46 -> 0.00071627648
B38: NAPS-GUANAJUATO NORTH WIRE INC | C38: 20580.62 | D38: =+C38/$C$46 -> 0.00050389555
B39: HM ULUSLARARASI PROJE TASIMACILIGI A.S | C39: 8992.8525 | D39: =+C39/$C$46 -> 0.00022018085
B40: SOLUCIONES LOGISTICAS Q DE MEXICO | C40: 6233.25 | D40: =+C40/$C$46 -> 0.00015261479
B41: DIGIT AUTOMOTIVE DE MEXICO | C41: 5066.33 | D41: =+C41/$C$46 -> 0.00012404394
B42: INNOVATIVE PORTING SL | C42: 4815.5495 | D42: =+C42/$C$46 -> 0.00011790383
B43: DISTRIBUIDORA DE HERRAMIENTAS UNICORNIO | C43: 4500 | D43: =+C43/$C$46 -> 0.00011017792
B44: DESCAFEINADORES MEXICANOS | C44: 3140.5635 | D44: =+C44/$C$46 -> 7.6893504e-05
B46: Total general | C46: =SUM(C10:C45) -> 40843028
C47: =+C46-K35 -> 1.292673

Sheet Por Oficina
B7: CORE GLOBAL LOGISTICS MANAGEMENT SA DE CV
B8: FACTURACIÓN MENSUAL POR OFICINA 2025
B9: CIFRAS EXPRESADAS EN PESOS SIN IVA
C10: Oficina
B11: Mes | C11: Nuevo Laredo | D11: Veracruz | E11: Total general
B12: Enero | C12: 815577.36 | D12: 2968654.3 | E12: =+SUM(C12:D12) -> 3784231.7
B13: Febrero | C13: 982121.86 | D13: 1182608.3 | E13: =+SUM(C13:D13) -> 2164730.2
B14: Marzo | C14: 1133086.8 | D14: 1914466.4 | E14: =+SUM(C14:D14) -> 3047553.1
B15: Abril | C15: 842176.5 | D15: 1205952.4 | E15: =+SUM(C15:D15) -> 2048128.9
B16: Mayo | C16: 1017639.3 | D16: 3626842 | E16: =+SUM(C16:D16) -> 4644481.3
B17: Junio | C17: 642516 | D17: 1878135.7 | E17: =+SUM(C17:D17) -> 2520651.7
B18: Julio | C18: 1344354.9 | D18: 4978802.9 | E18: =+SUM(C18:D18) -> 6323157.8
B19: Agosto | C19: 1026230.1 | D19: 2787063 | E19: =+SUM(C19:D19) -> 3813293
B20: Sepiembre | C20: 455362.33 | D20: 1322229.3 | E20: =+SUM(C20:D20) -> 1777591.6
B21: Octubre | C21: 597699.56 | D21: 2318542.1 | E21: =+SUM(C21:D21) -> 2916241.6
B22: Noviembre | C22: 717989.16 | D22: 3275137 | E22: =+SUM(C22:D22) -> 3993126.2
B23: Diciembre | C23: 1371249.6 | D23: 2438589.4 | E23: =+SUM(C23:D23) -> 3809839.1
B24: TOTAL | C24: =+SUM(C12:C23) -> 10946004 | D24: =+SUM(D12:D23) -> 29897023 | E24: =+SUM(E12:E23) -> 40843026
C27: =+C24/E24 -> 0.26800177 | D27: =+D24/E24 -> 0.73199823

Sheet Mensual por Cliente 2025
B2: CORE GLOBAL LOGISTICS MANAGEMENT, S.A. DE C.V.
B3: FACTURACIÓN MENSUAL POR CLIENTE
B4: =+'Acumulado 2025'!B7 -> FACTURACIÓN ACUMULADA DEL 1o DE ENERO AL 31 de Diciembre 2025
B5: NOMBRE DEL CLIENTE | C5: ENERO | D5: FEBRERO | E5: MARZO | F5: ABRIL | G5: MAYO | H5: JUNIO | I5: JULIO | J5: AGOSTO | K5: SEPTIEMBRE | L5: OCTUBRE | M5: NOVIEMBRE | N5: DICIEMBRE | O5: TOTAL
B6: JOINT PRODUCTION HONOR | C6: 393652.11 | D6: 216258.51 | E6: 73284.25 | F6: 54738.47 | G6: 2604790.4 | H6: 929149.66 | I6: 3494618.6 | J6: 1800483.1 | K6: 489112.45 | L6: 1439629.8 | M6: 2604841.2 | N6: 2123342.8 | O6: =+SUM(C6:N6) -> 16223901
B7: ARMOR MEXICO IMAGING SUPPLIES | C7: 812727.3 | D7: 583487.74 | E7: 554042.46 | F7: 600542.59 | G7: 726680.34 | H7: 916474.36 | I7: 926387.77 | J7: 550795.02 | K7: 526957.57 | L7: 671965.98 | M7: 831416.9 | N7: 486828.4 | O7: =+SUM(C7:N7) -> 8188306.4
B8: NAPS-GUANAJUATO AMERICAN BOA | C8: 443908.74 | D8: 338961.89 | E8: 765478.37 | F8: 468712.31 | G8: 259336.95 | I8: 50489.73 | J8: 23920.73 | K8: 15008.42 | L8: 11103.59 | M8: 10475.05 | N8: 11541.85 | O8: =+SUM(C8:N8) -> 2398937.6
B9: NAPS-GUANAJUATO CAM | C9: 262218.11 | D9: 238568.39 | E9: 576665.92 | F9: 304452.31 | G9: 377566.35 | H9: 276074.54 | I9: 518229 | J9: 320902.36 | K9: 301236.8 | L9: 148029 | M9: 106320.84 | N9: 201916.35 | O9: =+SUM(C9:N9) -> 3632180
B10: INVICONT OÜ | C10: 1230867.4 | E10: 171906.8 | O10: =+SUM(C10:N10) -> 1402774.2
B11: JOINT PRODUCTION TECTRAN | C11: 421264.96 | D11: 220293.62 | E11: 307817.2 | F11: 237561.6 | G11: 162415.36 | H11: 21000 | I11: 123080.73 | J11: 187046.2 | K11: 34777.33 | L11: 343000.14 | M11: 49726.57 | N11: 161751.22 | O11: =+SUM(C11:N11) -> 2269734.9
B12: JOINT PRODUCTION BLACK SMITH | C12: 22000 | D12: 240000 | E12: 358140 | F12: 244110.76 | G12: 264680.31 | H12: 286000 | I12: 287900 | J12: 245000 | K12: 88000 | L12: 44000 | M12: 44000 | N12: 66000 | O12: =+SUM(C12:N12) -> 2189831.1
A13: CORPORATIVO ADUANAL ROBLES | B13: CORPORATIVO ADUANAL ROBLES | I13: 436050.55 | O13: =+SUM(C13:N13) -> 436050.55
B14: CHEMICAL COLOR DE MEXICO | C14: 83820.573 | D14: 97309 | E14: 82427.283 | F14: 92440.045 | G14: 79734 | H14: 86023.641 | I14: 30043.52 | J14: 153190.96 | K14: 151076.2 | L14: 126398.63 | O14: =+SUM(C14:N14) -> 982463.85
B15: MEGALUMINIO SERVICIOS | C15: 9653.43 | D15: 138518.57 | E15: 19500 | G15: 19500 | I15: 19500 | J15: 39000 | K15: 20447.42 | M15: 205330.03 | N15: 163348.29 | O15: =+SUM(C15:N15) -> 634797.74
B16: CORE GLOBAL TRANSPORT | C16: 29447.57 | D16: 46666.85 | G16: 57070.28 | I16: 169164 | J16: 198076.03 | L16: 16057.96 | M16: 10080 | O16: =+SUM(C16:N16) -> 526562.69
B17: TENDENCIA INTERIOR | I17: 139909.44 | J17: 253265.53 | K17: 2983.45 | O17: =+SUM(C17:N17) -> 396158.42
B18: ND AUTOMOTIVE SYSTEMS MEXICO | C18: 70594.963 | E18: 25217.02 | O18: =+SUM(C18:N18) -> 95811.983
B19: INTERIORISMO CORP | G19: 75686.926 | O19: =+SUM(C19:N19) -> 75686.926
B20: CLEVELAND DIE QUERETARO | E20: 34700 | F20: 38246.99 | K20: 28306.12 | O20: =+SUM(C20:N20) -> 101253.11
B21: SUPER POPULAR LOGISTICS | I21: 71322.24 | N21: 8624.02 | O21: =+SUM(C21:N21) -> 79946.26
B22: HAHN AUTOMATION | D22: 9336.15 | E22: 38448 | I22: 11448.47 | K22: 12650 | O22: =+SUM(C22:N22) -> 71882.62
B23: GOMSA INTEGRADORA | D23: 15550.012 | E23: 13959.774 | F23: 7323.855 | G23: 7151.36 | O23: =+SUM(C23:N23) -> 43985.001
B24: SELLOS Y RETENES DE SAN LUIS | C24: 4076.46 | D24: 10275.6 | E24: 7700.77 | G24: 8400 | H24: 4500 | I24: 7700 | J24: 5775 | K24: 10800 | L24: 9445 | M24: 5500 | N24: 10577.3 | O24: =+SUM(C24:N24) -> 84750.13
A25: NEXT LOGISTICS XXI S.L | B25: NEXT LOGISTICS XXI S.L | I25: 19647.39 | J25: 7835.184 | K25: 54445.76 | L25: 5148.98 | M25: 10274.15 | N25: 8773.06 | O25: =+SUM(C25:N25) -> 106124.52
B26: NAPS-JUAREZ | J26: 21769.67 | L26: 20470 | O26: =+SUM(C26:N26) -> 42239.67
B27: JOINT PRODUCTION (HCMF) | E27: 13718.71 | L27: 15536.19 | O27: =+SUM(C27:N27) -> 29254.9
B28: NAPS-GUANAJUATO MULTITECH | I28: 12600 | K28: 41790.66 | M28: 37680.98 | O28: =+SUM(C28:N28) -> 92071.64
B29: HM ULUSLARARASI PROJE TASIMACILIGI A.S | D29: 1547.7225 | E29: 4546.5675 | G29: 1469.1 | H29: 1429.4625 | O29: =+SUM(C29:N29) -> 8992.8525
B30: SOLUCIONES LOGISTICAS Q DE MEXICO | J30: 6233.25 | O30: =+SUM(C30:N30) -> 6233.25
B31: INNOVATIVE PORTING SL | D31: 4815.5495 | O31: =+SUM(C31:N31) -> 4815.5495
B32: DIGIT AUTOMOTIVE DE MEXICO | I32: 5066.33 | O32: =+SUM(C32:N32) -> 5066.33
B33: DESCAFEINADORES MEXICANOS | D33: 3140.5635 | O33: =+SUM(C33:N33) -> 3140.5635
B34: DISTRIBUIDORA DE HERRAMIENTAS UNICORNIO | L34: 4500 | O34: =+SUM(C34:N34) -> 4500
B35: JOINT PRODUCTION BOOTH | L35: 60956.42 | O35: =+SUM(C35:N35) -> 60956.42
B36: GSI FABRIL | M36: 56900.5 | N36: 16529.36 | O36: =+SUM(C36:N36) -> 73429.86
B37: NAPS-GUANAJUATO NORTH WIRE INC | M37: 20580.62 | O37: =+SUM(C37:N37) -> 20580.62
B38: LOGISTICA DE CARGA MORSAN | N38: 345585.99 | O38: =+SUM(C38:N38) -> 345585.99
B39: LOGISTICA MEXICANA PALCO | N39: 68579.17 | O39: =+SUM(C39:N39) -> 68579.17
B40: MORSAN LOGISTICS | N40: 136441.28 | O40: =+SUM(C40:N40) -> 136441.28
O41: =+SUM(C41:N41) -> 0
...

Sheet Por Trimestre 2024
B6: CORE GLOBAL LOGISTICS MANAGEMENT, S.A. DE C.V.
B7: FACTURACIÓN EJERCICIO 2025
B8: DEL 1ER , 2DO Y 3ER TRIMESTRE
B9: CIFRAS EXPRESADAS EN PESOS SIN IVA
C10: MONTO FACTURADO
B11: NOMBRE DEL CLIENTE | C11: T1 | D11: T2 | E11: T3 | F11: T4 | G11: TOTAL
B12: =+'Mensual por Cliente 2025'!B6 -> JOINT PRODUCTION HONOR | C12: =+'Mensual por Cliente 2025'!C6+'Mensual por Cliente 2025'!D6+'Mensual por Cliente 2025'!E6 -> 683194.87 | D12: =+'Mensual por Cliente 2025'!F6+'Mensual por Cliente 2025'!G6+'Mensual por Cliente 2025'!H6 -> 3588678.5 | E12: =+'Mensual por Cliente 2025'!I6+'Mensual por Cliente 2025'!J6+'Mensual por Cliente 2025'!K6 -> 5784214.2 | F12: =+'Mensual por Cliente 2025'!L6+'Mensual por Cliente 2025'!M6+'Mensual por Cliente 2025'!N6 -> 6167813.8 | G12: =+SUM(C12:F12) -> 16223901
B13: =+'Mensual por Cliente 2025'!B7 -> ARMOR MEXICO IMAGING SUPPLIES | C13: =+'Mensual por Cliente 2025'!C7+'Mensual por Cliente 2025'!D7+'Mensual por Cliente 2025'!E7 -> 1950257.5 | D13: =+'Mensual por Cliente 2025'!F7+'Mensual por Cliente 2025'!G7+'Mensual por Cliente 2025'!H7 -> 2243697.3 | E13: =+'Mensual por Cliente 2025'!I7+'Mensual por Cliente 2025'!J7+'Mensual por Cliente 2025'!K7 -> 2004140.4 | F13: =+'Mensual por Cliente 2025'!L7+'Mensual por Cliente 2025'!M7+'Mensual por Cliente 2025'!N7 -> 1990211.3 | G13: =+SUM(C13:F13) -> 8188306.4
B14: =+'Mensual por Cliente 2025'!B8 -> NAPS-GUANAJUATO AMERICAN BOA | C14: =+'Mensual por Cliente 2025'!C8+'Mensual por Cliente 2025'!D8+'Mensual por Cliente 2025'!E8 -> 1548349 | D14: =+'Mensual por Cliente 2025'!F8+'Mensual por Cliente 2025'!G8+'Mensual por Cliente 2025'!H8 -> 728049.26 | E14: =+'Mensual por Cliente 2025'!I8+'Mensual por Cliente 2025'!J8+'Mensual por Cliente 2025'!K8 -> 89418.88 | F14: =+'Mensual por Cliente 2025'!L8+'Mensual por Cliente 2025'!M8+'Mensual por Cliente 2025'!N8 -> 33120.49 | G14: =+SUM(C14:F14) -> 2398937.6
B15: =+'Mensual por Cliente 2025'!B9 -> NAPS-GUANAJUATO CAM | C15: =+'Mensual por Cliente 2025'!C9+'Mensual por Cliente 2025'!D9+'Mensual por Cliente 2025'!E9 -> 1077452.4 | D15: =+'Mensual por Cliente 2025'!F9+'Mensual por Cliente 2025'!G9+'Mensual por Cliente 2025'!H9 -> 958093.2 | E15: =+'Mensual por Cliente 2025'!I9+'Mensual por Cliente 2025'!J9+'Mensual por Cliente 2025'!K9 -> 1140368.2 | F15: =+'Mensual por Cliente 2025'!L9+'Mensual por Cliente 2025'!M9+'Mensual por Cliente 2025'!N9 -> 456266.19 | G15: =+SUM(C15:F15) -> 3632180
B16: =+'Mensual por Cliente 2025'!B10 -> INVICONT OÜ | C16: =+'Mensual por Cliente 2025'!C10+'Mensual por Cliente 2025'!D10+'Mensual por Cliente 2025'!E10 -> 1402774.2 | D16: =+'Mensual por Cliente 2025'!F10+'Mensual por Cliente 2025'!G10+'Mensual por Cliente 2025'!H10 -> 0 | E16: =+'Mensual por Cliente 2025'!I10+'Mensual por Cliente 2025'!J10 -> 0 | F16: =+'Mensual por Cliente 2025'!L10+'Mensual por Cliente 2025'!M10 -> 0 | G16: =+SUM(C16:F16) -> 1402774.2
B17: =+'Mensual por Cliente 2025'!B11 -> JOINT PRODUCTION TECTRAN | C17: =+'Mensual por Cliente 2025'!C11+'Mensual por Cliente 2025'!D11+'Mensual por Cliente 2025'!E11 -> 949375.78 | D17: =+'Mensual por Cliente 2025'!F11+'Mensual por Cliente 2025'!G11+'Mensual por Cliente 2025'!H11 -> 420976.96 | E17: =+'Mensual por Cliente 2025'!I11+'Mensual por Cliente 2025'!J11+'Mensual por Cliente 2025'!K11 -> 344904.26 | F17: =+'Mensual por Cliente 2025'!L11+'Mensual por Cliente 2025'!M11+'Mensual por Cliente 2025'!N11 -> 554477.93 | G17: =+SUM(C17:F17) -> 2269734.9
B18: =+'Mensual por Cliente 2025'!B12 -> JOINT PRODUCTION BLACK SMITH | C18: =+'Mensual por Cliente 2025'!C12+'Mensual por Cliente 2025'!D12+'Mensual por Cliente 2025'!E12 -> 620140 | D18: =+'Mensual por Cliente 2025'!F12+'Mensual por Cliente 2025'!G12+'Mensual por Cliente 2025'!H12 -> 794791.07 | E18: =+'Mensual por Cliente 2025'!I12+'Mensual por Cliente 2025'!J12+'Mensual por Cliente 2025'!K12 -> 620900 | F18: =+'Mensual por Cliente 2025'!L12+'Mensual por Cliente 2025'!M12+'Mensual por Cliente 2025'!N12 -> 154000 | G18: =+SUM(C18:F18) -> 2189831.1
B19: =+'Mensual por Cliente 2025'!B13 -> CORPORATIVO ADUANAL ROBLES | C19: =+'Mensual por Cliente 2025'!C13+'Mensual por Cliente 2025'!D13+'Mensual por Cliente 2025'!E13 -> 0 | D19: =+'Mensual por Cliente 2025'!F13+'Mensual por Cliente 2025'!G13+'Mensual por Cliente 2025'!H13 -> 0 | E19: =+'Mensual por Cliente 2025'!I13+'Mensual por Cliente 2025'!J13 -> 436050.55 | F19: =+'Mensual por Cliente 2025'!L13+'Mensual por Cliente 2025'!M13 -> 0 | G19: =+SUM(C19:F19) -> 436050.55
B20: =+'Mensual por Cliente 2025'!B14 -> CHEMICAL COLOR DE MEXICO | C20: =+'Mensual por Cliente 2025'!C14+'Mensual por Cliente 2025'!D14+'Mensual por Cliente 2025'!E14 -> 263556.86 | D20: =+'Mensual por Cliente 2025'!F14+'Mensual por Cliente 2025'!G14+'Mensual por Cliente 2025'!H14 -> 258197.69 | E20: =+'Mensual por Cliente 2025'!I14+'Mensual por Cliente 2025'!J14+'Mensual por Cliente 2025'!K14 -> 334310.68 | F20: =+'Mensual por Cliente 2025'!L14+'Mensual por Cliente 2025'!M14 -> 126398.63 | G20: =+SUM(C20:F20) -> 982463.85
B21: =+'Mensual por Cliente 2025'!B15 -> MEGALUMINIO SERVICIOS | C21: =+'Mensual por Cliente 2025'!C15+'Mensual por Cliente 2025'!D15+'Mensual por Cliente 2025'!E15 -> 167672 | D21: =+'Mensual por Cliente 2025'!F15+'Mensual por Cliente 2025'!G15+'Mensual por Cliente 2025'!H15 -> 19500 | E21: =+'Mensual por Cliente 2025'!I15+'Mensual por Cliente 2025'!J15+'Mensual por Cliente 2025'!K15 -> 78947.42 | F21: =+'Mensual por Cliente 2025'!L15+'Mensual por Cliente 2025'!M15+'Mensual por Cliente 2025'!N15 -> 368678.32 | G21: =+SUM(C21:F21) -> 634797.74
B22: =+'Mensual por Cliente 2025'!B16 -> CORE GLOBAL TRANSPORT | C22: =+'Mensual por Cliente 2025'!C16+'Mensual por Cliente 2025'!D16+'Mensual por Cliente 2025'!E16 -> 76114.42 | D22: =+'Mensual por Cliente 2025'!F16+'Mensual por Cliente 2025'!G16+'Mensual por Cliente 2025'!H16 -> 57070.28 | E22: =+'Mensual por Cliente 2025'!I16+'Mensual por Cliente 2025'!J16 -> 367240.03 | F22: =+'Mensual por Cliente 2025'!L16+'Mensual por Cliente 2025'!M16 -> 26137.96 | G22: =+SUM(C22:F22) -> 526562.69 | I22: Trimestre 1 | J22: =+C48 -> 8996514.9 | K22: =+J22/$J$26 -> 0.22027052
B23: =+'Mensual por Cliente 2025'!B17 -> TENDENCIA INTERIOR | C23: =+'Mensual por Cliente 2025'!C17+'Mensual por Cliente 2025'!D17+'Mensual por Cliente 2025'!E17 -> 0 | D23: =+'Mensual por Cliente 2025'!F17+'Mensual por Cliente 2025'!G17+'Mensual por Cliente 2025'!H17 -> 0 | E23: =+'Mensual por Cliente 2025'!I17+'Mensual por Cliente 2025'!J17+'Mensual por Cliente 2025'!K17 -> 396158.42 | F23: =+'Mensual por Cliente 2025'!L17+'Mensual por Cliente 2025'!M17 -> 0 | G23: =+SUM(C23:F23) -> 396158.42 | I23: Trimestre 2 | J23: =+D48 -> 9213261.9 | K23: =+J23/$J$26 -> 0.22557735
B24: =+'Mensual por Cliente 2025'!B18 -> ND AUTOMOTIVE SYSTEMS MEXICO | C24: =+'Mensual por Cliente 2025'!C18+'Mensual por Cliente 2025'!D18+'Mensual por Cliente 2025'!E18 -> 95811.983 | D24: =+'Mensual por Cliente 2025'!F18+'Mensual por Cliente 2025'!G18+'Mensual por Cliente 2025'!H18 -> 0 | E24: =+'Mensual por Cliente 2025'!I18+'Mensual por Cliente 2025'!J18 -> 0 | F24: =+'Mensual por Cliente 2025'!L18+'Mensual por Cliente 2025'!M18 -> 0 | G24: =+SUM(C24:F24) -> 95811.983 | I24: Trimestre 3 | J24: =+E48 -> 11914043 | K24: =+J24/$J$26 -> 0.29170323
B25: =+'Mensual por Cliente 2025'!B19 -> INTERIORISMO CORP | C25: =+'Mensual por Cliente 2025'!C19+'Mensual por Cliente 2025'!D19+'Mensual por Cliente 2025'!E19 -> 0 | D25: =+'Mensual por Cliente 2025'!F19+'Mensual por Cliente 2025'!G19+'Mensual por Cliente 2025'!H19 -> 75686.926 | E25: =+'Mensual por Cliente 2025'!I19+'Mensual por Cliente 2025'!J19 -> 0 | F25: =+'Mensual por Cliente 2025'!L19+'Mensual por Cliente 2025'!M19 -> 0 | G25: =+SUM(C25:F25) -> 75686.926 | I25: Trimestre 4 | J25: =+F48 -> 10719208 | K25: =+J25/$J$26 -> 0.2624489
B26: =+'Mensual por Cliente 2025'!B20 -> CLEVELAND DIE QUERETARO | C26: =+'Mensual por Cliente 2025'!C20+'Mensual por Cliente 2025'!D20+'Mensual por Cliente 2025'!E20 -> 34700 | D26: =+'Mensual por Cliente 2025'!F20+'Mensual por Cliente 2025'!G20+'Mensual por Cliente 2025'!H20 -> 38246.99 | E26: =+'Mensual por Cliente 2025'!I20+'Mensual por Cliente 2025'!J20+'Mensual por Cliente 2025'!K20 -> 28306.12 | F26: =+'Mensual por Cliente 2025'!L20+'Mensual por Cliente 2025'!M20 -> 0 | G26: =+SUM(C26:F26) -> 101253.11 | J26: =+SUM(J22:J25) -> 40843028
B27: =+'Mensual por Cliente 2025'!B21 -> SUPER POPULAR LOGISTICS | C27: =+'Mensual por Cliente 2025'!C21+'Mensual por Cliente 2025'!D21+'Mensual por Cliente 2025'!E21 -> 0 | D27: =+'Mensual por Cliente 2025'!F21+'Mensual por Cliente 2025'!G21+'Mensual por Cliente 2025'!H21 -> 0 | E27: =+'Mensual por Cliente 2025'!I21+'Mensual por Cliente 2025'!J21 -> 71322.24 | F27: =+'Mensual por Cliente 2025'!N21 -> 8624.02 | G27: =+SUM(C27:F27) -> 79946.26
B28: =+'Mensual por Cliente 2025'!B22 -> HAHN AUTOMATION | C28: =+'Mensual por Cliente 2025'!C22+'Mensual por Cliente 2025'!D22+'Mensual por Cliente 2025'!E22 -> 47784.15 | D28: =+'Mensual por Cliente 2025'!F22+'Mensual por Cliente 2025'!G22+'Mensual por Cliente 2025'!H22 -> 0 | E28: =+'Mensual por Cliente 2025'!I22+'Mensual por Cliente 2025'!J22+'Mensual por Cliente 2025'!K22 -> 24098.47 | F28: =+'Mensual por Cliente 2025'!L22+'Mensual por Cliente 2025'!M22 -> 0 | G28: =+SUM(C28:F28) -> 71882.62
B29: =+'Mensual por Cliente 2025'!B23 -> GOMSA INTEGRADORA | C29: =+'Mensual por Cliente 2025'!C23+'Mensual por Cliente 2025'!D23+'Mensual por Cliente 2025'!E23 -> 29509.786 | D29: =+'Mensual por Cliente 2025'!F23+'Mensual por Cliente 2025'!G23+'Mensual por Cliente 2025'!H23 -> 14475.215 | E29: =+'Mensual por Cliente 2025'!I23+'Mensual por Cliente 2025'!J23 -> 0 | F29: =+'Mensual por Cliente 2025'!L23+'Mensual por Cliente 2025'!M23 -> 0 | G29: =+SUM(C29:F29) -> 43985.001
B30: =+'Mensual por Cliente 2025'!B24 -> SELLOS Y RETENES DE SAN LUIS | C30: =+'Mensual por Cliente 2025'!C24+'Mensual por Cliente 2025'!D24+'Mensual por Cliente 2025'!E24 -> 22052.83 | D30: =+'Mensual por Cliente 2025'!F24+'Mensual por Cliente 2025'!G24+'Mensual por Cliente 2025'!H24 -> 12900 | E30: =+'Mensual por Cliente 2025'!I24+'Mensual por Cliente 2025'!J24+'Mensual por Cliente 2025'!K24 -> 24275 | F30: =+'Mensual por Cliente 2025'!L24+'Mensual por Cliente 2025'!M24+'Mensual por Cliente 2025'!N24 -> 25522.3 | G30: =+SUM(C30:F30) -> 84750.13
B31: =+'Mensual por Cliente 2025'!B25 -> NEXT LOGISTICS XXI S.L | C31: =+'Mensual por Cliente 2025'!C25+'Mensual por Cliente 2025'!D25+'Mensual por Cliente 2025'!E25 -> 0 | D31: =+'Mensual por Cliente 2025'!F25+'Mensual por Cliente 2025'!G25+'Mensual por Cliente 2025'!H25 -> 0 | E31: =+'Mensual por Cliente 2025'!I25+'Mensual por Cliente 2025'!J25+'Mensual por Cliente 2025'!K25 -> 81928.334 | F31: =+'Mensual por Cliente 2025'!L25+'Mensual por Cliente 2025'!M25+'Mensual por Cliente 2025'!N25 -> 24196.19 | G31: =+SUM(C31:F31) -> 106124.52
B32: =+'Mensual por Cliente 2025'!B26 -> NAPS-JUAREZ | C32: =+'Mensual por Cliente 2025'!C26+'Mensual por Cliente 2025'!D26+'Mensual por Cliente 2025'!E26 -> 0 | D32: =+'Mensual por Cliente 2025'!F26+'Mensual por Cliente 2025'!G26+'Mensual por Cliente 2025'!H26 -> 0 | E32: =+'Mensual por Cliente 2025'!I26+'Mensual por Cliente 2025'!J26 -> 21769.67 | F32: =+'Mensual por Cliente 2025'!L26+'Mensual por Cliente 2025'!M26 -> 20470 | G32: =+SUM(C32:F32) -> 42239.67
B33: =+'Mensual por Cliente 2025'!B27 -> JOINT PRODUCTION (HCMF) | C33: =+'Mensual por Cliente 2025'!C27+'Mensual por Cliente 2025'!D27+'Mensual por Cliente 2025'!E27 -> 13718.71 | D33: =+'Mensual por Cliente 2025'!F27+'Mensual por Cliente 2025'!G27+'Mensual por Cliente 2025'!H27 -> 0 | E33: =+'Mensual por Cliente 2025'!I27+'Mensual por Cliente 2025'!J27 -> 0 | F33: =+'Mensual por Cliente 2025'!L27+'Mensual por Cliente 2025'!M27 -> 15536.19 | G33: =+SUM(C33:F33) -> 29254.9
B34: =+'Mensual por Cliente 2025'!B28 -> NAPS-GUANAJUATO MULTITECH | C34: =+'Mensual por Cliente 2025'!C28+'Mensual por Cliente 2025'!D28+'Mensual por Cliente 2025'!E28 -> 0 | D34: =+'Mensual por Cliente 2025'!F28+'Mensual por Cliente 2025'!G28+'Mensual por Cliente 2025'!H28 -> 0 | E34: =+'Mensual por Cliente 2025'!I28+'Mensual por Cliente 2025'!J28+'Mensual por Cliente 2025'!K28 -> 54390.66 | F34: =+'Mensual por Cliente 2025'!L28+'Mensual por Cliente 2025'!M28 -> 37680.98 | G34: =+SUM(C34:F34) -> 92071.64
B35: =+'Mensual por Cliente 2025'!B29 -> HM ULUSLARARASI PROJE TASIMACILIGI A.S | C35: =+'Mensual por Cliente 2025'!C29+'Mensual por Cliente 2025'!D29+'Mensual por Cliente 2025'!E29 -> 6094.29 | D35: =+'Mensual por Cliente 2025'!F29+'Mensual por Cliente 2025'!G29+'Mensual por Cliente 2025'!H29 -> 2898.5625 | E35: =+'Mensual por Cliente 2025'!I29+'Mensual por Cliente 2025'!J29 -> 0 | F35: =+'Mensual por Cliente 2025'!L29+'Mensual por Cliente 2025'!M29 -> 0 | G35: =+SUM(C35:F35) -> 8992.8525
B36: =+'Mensual por Cliente 2025'!B30 -> SOLUCIONES LOGISTICAS Q DE MEXICO | C36: =+'Mensual por Cliente 2025'!C30+'Mensual por Cliente 2025'!D30+'Mensual por Cliente 2025'!E30 -> 0 | D36: =+'Mensual por Cliente 2025'!F30+'Mensual por Cliente 2025'!G30+'Mensual por Cliente 2025'!H30 -> 0 | E36: =+'Mensual por Cliente 2025'!I30+'Mensual por Cliente 2025'!J30 -> 6233.25 | F36: =+'Mensual por Cliente 2025'!L30+'Mensual por Cliente 2025'!M30 -> 0 | G36: =+SUM(C36:F36) -> 6233.25
B37: =+'Mensual por Cliente 2025'!B31 -> INNOVATIVE PORTING SL | C37: =+'Mensual por Cliente 2025'!C31+'Mensual por Cliente 2025'!D31+'Mensual por Cliente 2025'!E31 -> 4815.5495 | D37: =+'Mensual por Cliente 2025'!F31+'Mensual por Cliente 2025'!G31+'Mensual por Cliente 2025'!H31 -> 0 | E37: =+'Mensual por Cliente 2025'!I31+'Mensual por Cliente 2025'!J31 -> 0 | F37: =+'Mensual por Cliente 2025'!L31+'Mensual por Cliente 2025'!M31 -> 0 | G37: =+SUM(C37:F37) -> 4815.5495
B38: =+'Mensual por Cliente 2025'!B32 -> DIGIT AUTOMOTIVE DE MEXICO | C38: =+'Mensual por Cliente 2025'!C32+'Mensual por Cliente 2025'!D32+'Mensual por Cliente 2025'!E32 -> 0 | D38: =+'Mensual por Cliente 2025'!F32+'Mensual por Cliente 2025'!G32+'Mensual por Cliente 2025'!H32 -> 0 | E38: =+'Mensual por Cliente 2025'!I32+'Mensual por Cliente 2025'!J32 -> 5066.33 | F38: =+'Mensual por Cliente 2025'!L32+'Mensual por Cliente 2025'!M32 -> 0 | G38: =+SUM(C38:F38) -> 5066.33
B39: =+'Mensual por Cliente 2025'!B33 -> DESCAFEINADORES MEXICANOS | C39: =+'Mensual por Cliente 2025'!C33+'Mensual por Cliente 2025'!D33+'Mensual por Cliente 2025'!E33 -> 3140.5635 | D39: =+'Mensual por Cliente 2025'!F33+'Mensual por Cliente 2025'!G33+'Mensual por Cliente 2025'!H33 -> 0 | E39: =+'Mensual por Cliente 2025'!I33+'Mensual por Cliente 2025'!J33 -> 0 | F39: =+'Mensual por Cliente 2025'!L33+'Mensual por Cliente 2025'!M33 -> 0 | G39: =+SUM(C39:F39) -> 3140.5635
B40: DISTRIBUIDORA DE HERRAMIENTAS UNICORNIO | C40: =+'Mensual por Cliente 2025'!C34+'Mensual por Cliente 2025'!D34+'Mensual por Cliente 2025'!E34 -> 0 | D40: =+'Mensual por Cliente 2025'!F34+'Mensual por Cliente 2025'!G34+'Mensual por Cliente 2025'!H34 -> 0 | E40: =+'Mensual por Cliente 2025'!I34+'Mensual por Cliente 2025'!J34 -> 0 | F40: =+'Mensual por Cliente 2025'!L34+'Mensual por Cliente 2025'!M34 -> 4500 | G40: =+SUM(C40:F40) -> 4500
B41: JOINT PRODUCTION BOOTH | C41: =+'Mensual por Cliente 2025'!C35+'Mensual por Cliente 2025'!D35+'Mensual por Cliente 2025'!E35 -> 0 | D41: =+'Mensual por Cliente 2025'!F35+'Mensual por Cliente 2025'!G35+'Mensual por Cliente 2025'!H35 -> 0 | E41: =+'Mensual por Cliente 2025'!I35+'Mensual por Cliente 2025'!J35 -> 0 | F41: =+'Mensual por Cliente 2025'!L35+'Mensual por Cliente 2025'!M35 -> 60956.42 | G41: =+SUM(C41:F41) -> 60956.42
B42: GSI FABRIL | C42: =+'Mensual por Cliente 2025'!C36+'Mensual por Cliente 2025'!D36+'Mensual por Cliente 2025'!E36 -> 0 | D42: =+'Mensual por Cliente 2025'!F36+'Mensual por Cliente 2025'!G36+'Mensual por Cliente 2025'!H36 -> 0 | E42: =+'Mensual por Cliente 2025'!I36+'Mensual por Cliente 2025'!J36 -> 0 | F42: =+'Mensual por Cliente 2025'!L36+'Mensual por Cliente 2025'!M36+'Mensual por Cliente 2025'!N36 -> 73429.86 | G42: =+SUM(C42:F42) -> 73429.86
B43: NAPS-GUANAJUATO NORTH WIRE INC | C43: =+'Mensual por Cliente 2025'!C37+'Mensual por Cliente 2025'!D37+'Mensual por Cliente 2025'!E37 -> 0 | D43: =+'Mensual por Cliente 2025'!F37+'Mensual por Cliente 2025'!G37+'Mensual por Cliente 2025'!H37 -> 0 | E43: =+'Mensual por Cliente 2025'!I37+'Mensual por Cliente 2025'!J37 -> 0 | F43: =+'Mensual por Cliente 2025'!L37+'Mensual por Cliente 2025'!M37 -> 20580.62 | G43: =+SUM(C43:F43) -> 20580.62
B44: LOGISTICA DE CARGA MORSAN | C44: 0 | D44: 0 | E44: 0 | F44: =+'Mensual por Cliente 2025'!N38 -> 345585.99 | G44: =+SUM(C44:F44) -> 345585.99
B45: LOGISTICA MEXICANA PALCO | C45: 0 | D45: 0 | E45: 0 | F45: =+'Mensual por Cliente 2025'!N39 -> 68579.17 | G45: =+SUM(C45:F45) -> 68579.17
...

Sheet Por Tipo
B2: CORE GLOBAL LOGISTICS MANAGEMENT, S.A. DE C.V.
B3: FACTURACIÓN EJERCICIO 2025
B4: CIFRAS EXPRESADAS EN PESOS SIN IVA
C5: MONTO FACTURADO
B6: NOMBRE DEL CLIENTE | C6: NUEVAS | D6: ORDINARIAS | E6: TOTAL
B7: =+'Por Trimestre 2024'!B12 -> JOINT PRODUCTION HONOR | D7: =+'Mensual por Cliente 2025'!O6 -> 16223901 | E7: =+C7+D7 -> 16223901
B8: =+'Por Trimestre 2024'!B13 -> ARMOR MEXICO IMAGING SUPPLIES | D8: =+'Mensual por Cliente 2025'!O7 -> 8188306.4 | E8: =+C8+D8 -> 8188306.4
B9: =+'Por Trimestre 2024'!B14 -> NAPS-GUANAJUATO AMERICAN BOA | D9: =+'Mensual por Cliente 2025'!O8 -> 2398937.6 | E9: =+C9+D9 -> 2398937.6
B10: =+'Por Trimestre 2024'!B15 -> NAPS-GUANAJUATO CAM | D10: =+'Mensual por Cliente 2025'!O9 -> 3632180 | E10: =+C10+D10 -> 3632180
B11: =+'Por Trimestre 2024'!B16 -> INVICONT OÜ | C11: 1402774.2 | E11: =+C11+D11 -> 1402774.2
B12: =+'Por Trimestre 2024'!B17 -> JOINT PRODUCTION TECTRAN | D12: =+'Mensual por Cliente 2025'!O11 -> 2269734.9 | E12: =+C12+D12 -> 2269734.9
B13: =+'Por Trimestre 2024'!B18 -> JOINT PRODUCTION BLACK SMITH | D13: =+'Mensual por Cliente 2025'!O12 -> 2189831.1 | E13: =+C13+D13 -> 2189831.1
B14: =+'Por Trimestre 2024'!B19 -> CORPORATIVO ADUANAL ROBLES | D14: =+'Mensual por Cliente 2025'!O13 -> 436050.55 | E14: =+C14+D14 -> 436050.55
B15: =+'Por Trimestre 2024'!B20 -> CHEMICAL COLOR DE MEXICO | C15: =+'Mensual por Cliente 2025'!O14 -> 982463.85 | E15: =+C15+D15 -> 982463.85
B16: =+'Por Trimestre 2024'!B21 -> MEGALUMINIO SERVICIOS | D16: =+'Mensual por Cliente 2025'!O15 -> 634797.74 | E16: =+C16+D16 -> 634797.74
B17: =+'Por Trimestre 2024'!B22 -> CORE GLOBAL TRANSPORT | D17: =+'Mensual por Cliente 2025'!O16 -> 526562.69 | E17: =+C17+D17 -> 526562.69
B18: =+'Por Trimestre 2024'!B23 -> TENDENCIA INTERIOR | D18: =+'Mensual por Cliente 2025'!O17 -> 396158.42 | E18: =+C18+D18 -> 396158.42
B19: =+'Por Trimestre 2024'!B24 -> ND AUTOMOTIVE SYSTEMS MEXICO | D19: =+'Mensual por Cliente 2025'!O18 -> 95811.983 | E19: =+C19+D19 -> 95811.983
B20: =+'Por Trimestre 2024'!B25 -> INTERIORISMO CORP | D20: =+'Mensual por Cliente 2025'!O19 -> 75686.926 | E20: =+C20+D20 -> 75686.926
B21: =+'Por Trimestre 2024'!B26 -> CLEVELAND DIE QUERETARO | D21: =+'Mensual por Cliente 2025'!O20 -> 101253.11 | E21: =+C21+D21 -> 101253.11
B22: =+'Por Trimestre 2024'!B27 -> SUPER POPULAR LOGISTICS | C22: =+'Mensual por Cliente 2025'!O21 -> 79946.26 | E22: =+C22+D22 -> 79946.26
B23: =+'Por Trimestre 2024'!B28 -> HAHN AUTOMATION | D23: =+'Mensual por Cliente 2025'!O22 -> 71882.62 | E23: =+C23+D23 -> 71882.62 | G23: Nuevas | H23: =+C43 -> 3350733.2 | I23: =+H23/$H$25 -> 0.082039295
B24: =+'Por Trimestre 2024'!B29 -> GOMSA INTEGRADORA | C24: 43985.001 | E24: =+C24+D24 -> 43985.001 | G24: Ordinarias | H24: =+D43 -> 37492294 | I24: =+H24/$H$25 -> 0.91796071
B25: =+'Por Trimestre 2024'!B30 -> SELLOS Y RETENES DE SAN LUIS | D25: =+'Mensual por Cliente 2025'!O24 -> 84750.13 | E25: =+C25+D25 -> 84750.13 | H25: =+SUM(H23:H24) -> 40843028
B26: =+'Por Trimestre 2024'!B31 -> NEXT LOGISTICS XXI S.L | C26: =+'Mensual por Cliente 2025'!O25 -> 106124.52 | E26: =+C26+D26 -> 106124.52
B27: =+'Por Trimestre 2024'!B32 -> NAPS-JUAREZ | C27: =+'Mensual por Cliente 2025'!O26 -> 42239.67 | E27: =+C27+D27 -> 42239.67
B28: =+'Por Trimestre 2024'!B33 -> JOINT PRODUCTION (HCMF) | D28: =+'Mensual por Cliente 2025'!O27 -> 29254.9 | E28: =+C28+D28 -> 29254.9
B29: =+'Por Trimestre 2024'!B34 -> NAPS-GUANAJUATO MULTITECH | D29: =+'Mensual por Cliente 2025'!O28 -> 92071.64 | E29: =+C29+D29 -> 92071.64
B30: =+'Por Trimestre 2024'!B35 -> HM ULUSLARARASI PROJE TASIMACILIGI A.S | D30: =+'Mensual por Cliente 2025'!O29 -> 8992.8525 | E30: =+C30+D30 -> 8992.8525
B31: =+'Por Trimestre 2024'!B36 -> SOLUCIONES LOGISTICAS Q DE MEXICO | D31: =+'Mensual por Cliente 2025'!O30 -> 6233.25 | E31: =+C31+D31 -> 6233.25
B32: =+'Por Trimestre 2024'!B37 -> INNOVATIVE PORTING SL | D32: =+'Mensual por Cliente 2025'!O31 -> 4815.5495 | E32: =+C32+D32 -> 4815.5495
B33: =+'Por Trimestre 2024'!B38 -> DIGIT AUTOMOTIVE DE MEXICO | C33: 5066.33 | E33: =+C33+D33 -> 5066.33
B34: =+'Por Trimestre 2024'!B39 -> DESCAFEINADORES MEXICANOS | C34: 3140.5635 | E34: =+C34+D34 -> 3140.5635
B35: DISTRIBUIDORA DE HERRAMIENTAS UNICORNIO | D35: 4500 | E35: =+C35+D35 -> 4500
B36: JOINT PRODUCTION BOOTH | C36: =+'Mensual por Cliente 2025'!O35 -> 60956.42 | E36: =+C36+D36 -> 60956.42
B37: GSI FABRIL | C37: =+'Mensual por Cliente 2025'!O36 -> 73429.86 | E37: =+C37+D37 -> 73429.86
B38: NAPS-GUANAJUATO NORTH WIRE INC | D38: =+'Mensual por Cliente 2025'!O37 -> 20580.62 | E38: =+C38+D38 -> 20580.62
B39: LOGISTICA DE CARGA MORSAN | C39: =+'Mensual por Cliente 2025'!O38 -> 345585.99 | E39: =+C39+D39 -> 345585.99
B40: LOGISTICA MEXICANA PALCO | C40: =+'Mensual por Cliente 2025'!O39 -> 68579.17 | E40: =+C40+D40 -> 68579.17
B41: MORSAN LOGISTICS | C41: =+'Mensual por Cliente 2025'!O40 -> 136441.28 | E41: =+C41+D41 -> 136441.28
...

Sheet AC202
A1: OFICINA | B1: MES | C1: FACTURA | D1: TRAFICO | E1: FECHA | F1: CLIENTE | G1: CLIENTE NOMBRE | H1: IMPORTE | I1: PROFIT | J1: EJECUTIVO | K1: T OPERACIÓN
A2: NLD | B2: Enero | C2: 2-002317 | D2: CGL24122402 | E2: 45660 | F2: C0001 | G2: ARMOR MEXICO IMAGING SUPPLIES | H2: 16362.29 | I2: 0.423 | J2: JESSICA
A3: NLD | B3: Enero | C3: 2-002318 | D3: CGL24122374 | E3: 45660 | F3: C0001 | G3: ARMOR MEXICO IMAGING SUPPLIES | H3: 17562.29 | I3: 0.449 | J3: JESSICA
A4: VER | B4: Enero | C4: 1-002319 | D4: CGL24112354 | E4: 45660 | F4: C0001 | G4: ARMOR MEXICO IMAGING SUPPLIES | H4: 112970.32 | I4: 0.284 | J4: ISRAEL
A5: VER | B5: Enero | C5: 1-002320 | D5: CGL24122437 | E5: 45660 | F5: C0001 | G5: ARMOR MEXICO IMAGING SUPPLIES | H5: 3540 | I5: 0.259 | J5: ISRAEL
A6: NLD | B6: Enero | C6: 2-002321 | D6: CGL24122431 | E6: 45660 | F6: C0001 | G6: ARMOR MEXICO IMAGING SUPPLIES | H6: 2928.25 | I6: 0.59 | J6: JESSICA
A7: NLD | B7: Enero | C7: 2-002322 | D7: CGL24122391 | E7: 45660 | F7: C0001 | G7: ARMOR MEXICO IMAGING SUPPLIES | H7: 16361.73 | I7: 0.423 | J7: JESSICA
A8: VER | B8: Enero | C8: 1-002323 | D8: CGL24122418 | E8: 45660 | F8: C0001 | G8: ARMOR MEXICO IMAGING SUPPLIES | H8: 10620 | I8: 0.259 | J8: ISRAEL
A9: VER | B9: Enero | C9: 1-002324 | D9: CGL24112348 | E9: 45660 | F9: C0001 | G9: ARMOR MEXICO IMAGING SUPPLIES | H9: 79824.55 | I9: 0.225 | J9: ISRAEL
A10: NLD | B10: Enero | C10: 2-002325 | D10: CGL24122383 | E10: 45660 | F10: C0002 | G10: NAPS-GUANAJUATO CAM | H10: 6908.32 | I10: 0.551 | J10: NALLELY
A11: VER | B11: Enero | C11: 1-002326 | D11: CGL24082033 | E11: 45665 | F11: C0067 | G11: ND AUTOMOTIVE SYSTEMS MEXICO | H11: 0.01 | I11: 0 | J11: ALONSO
A12: VER | B12: Enero | C12: 1-002327 | D12: CGL24122395 | E12: 45666 | F12: C0001 | G12: ARMOR MEXICO IMAGING SUPPLIES | H12: 106812.52 | I12: 0.308 | J12: ISRAEL
A13: VER | B13: Enero | C13: 1-002328 | D13: CGL24122396 | E13: 45666 | F13: C0001 | G13: ARMOR MEXICO IMAGING SUPPLIES | H13: 84790.76 | I13: 0.293 | J13: ISRAEL
... A72: NLD | B72: Enero | C72: 2-002357 | D72: CGL24122435 | E72: 45680 | F72: C0084 | G72: JOINT PRODUCTION TECTRAN | H72: 140301.7 | I72: 0.175 | J72: ELIAS
A73: VER | B73: Enero | C73: 1-002358 | D73: CGL24122430 | E73: 45681 | F73: C0089 | G73: CHEMICAL COLOR DE MEXICO | H73: 83820.573 | I73: 0.346 | J73: ELIAS | K73: M
A74: VER | B74: Enero | C74: 1-002360 | D74: CGL24122432 | E74: 45681 | F74: C0001 | G74: ARMOR MEXICO IMAGING SUPPLIES | H74: 114208.08 | I74: 0.271 | J74: ISRAEL
A75: NLD | B75: Enero | C75: 2-002380 | D75: CGL25012470 | E75: 45687 | F75: C0084 | G75: JOINT PRODUCTION TECTRAN | H75: 125977.16 | I75: 0.205 | J75: ELIAS
A76: VER | B76: Enero | C76: 1-002381 | D76: CGL24122397 | E76: 45687 | F76: C0067 | G76: ND AUTOMOTIVE SYSTEMS MEXICO | H76: 7712.8875 | I76: 0.3 | J76: ALONSO
A77: VER | B77: Enero | C77: 1-002382 | D77: CGL24071864 | E77: 45687 | F77: C0067 | G77: ND AUTOMOTIVE SYSTEMS MEXICO | H77: 5141.925 | I77: 0.232 | J77: ALONSO
A78: VER | B78: Enero | C78: 1-002387 | D78: CGL25012469 | E78: 45688 | F78: C0090 | G78: INVICONT OÜ | H78: 1230867.4 | I78: -0.364 | J78: JESUS
A79: VER | B79: Febrero | C79: 1-002395 | D79: CGL24122432 | E79: 45694 | F79: C0001 | G79: ARMOR MEXICO IMAGING SUPPLIES | H79: 107360.24 | I79: 0.271 | J79: ISRAEL
A80: VER | B80: Febrero | C80: 1-002396 | D80: CGL25012475 | E80: 45694 | F80: C0001 | G80: ARMOR MEXICO IMAGING SUPPLIES | H80: 73868.29 | I80: 0.288 | J80: ISRAEL
A81: VER | B81: Febrero | C81: 1-002397 | D81: CGL25012515 | E81: 45694 | F81: C0069 | G81: JOINT PRODUCTION HONOR | H81: 13293.3 | I81: 0.414 | J81: ALONSO
A82: VER | B82: Febrero | C82: 1-002399 | D82: CGL25012513 | E82: 45694 | F82: C0004 | G82: NAPS-GUANAJUATO AMERICAN BOA | H82: 143742.45 | I82: 0.361 | J82: ELIAS
A83: NLD | B83: Febrero | C83: 2-002401 | D83: CGL25012522 | E83: 45695 | F83: C0001 | G83: ARMOR MEXICO IMAGING SUPPLIES | H83: 26000.04 | I83: 0.386 | J83: JESSICA
A84: NLD | B84: Febrero | C84: 2-002402 | D84: CGL25012464 | E84: 45695 | F84: C0069 | G84: JOINT PRODUCTION HONOR | H84: 15295.72 | I84: 0.856 | J84: JESSICA
A85: VER | B85: Febrero | C85: 1-002403 | D85: CGL25012501 | E85: 45699 | F85: C0084 | G85: JOINT PRODUCTION TECTRAN | H85: 21320.23 | I85: 0.259 | J85: ELIAS
... A124: NLD | B124: Febrero | C124: 2-002449 | D124: CGL25022563 | E124: 45708 | F124: C0002 | G124: NAPS-GUANAJUATO CAM | H124: 8047.47 | I124: 0.64 | J124: NALLELY
A125: VER | B125: Febrero | C125: 1-002450 | D125: CGL24122430 | E125: 45709 | F125: C0089 | G125: CHEMICAL COLOR DE MEXICO | H125: 95976 | I125: 0.346 | J125: ELIAS | K125: M
A126: VER | B126: Febrero | C126: 1-002451 | D126: CGL24122430 | E126: 45709 | F126: C0089 | G126: CHEMICAL COLOR DE MEXICO | H126: 1333 | I126: 0.346 | J126: ELIAS | K126: M
A127: NLD | B127: Febrero | C127: 2-002452 | D127: CGL25022554 | E127: 45709 | F127: C0002 | G127: NAPS-GUANAJUATO CAM | H127: 4133.86 | I127: 0.565 | J127: NALLELY
A128: NLD | B128: Febrero | C128: 2-002453 | D128: CGL25012447 | E128: 45709 | F128: C0002 | G128: NAPS-GUANAJUATO CAM | H128: 20348.24 | I128: 0.661 | J128: NALLELY
A129: NLD | B129: Febrero | C129: 2-002455 | D129: CGL25022581 | E129: 45712 | F129: C0001 | G129: ARMOR MEXICO IMAGING SUPPLIES | H129: 41061.64 | I129: 0.35 | J129: JESSICA
A130: VER | B130: Febrero | C130: 1-002456 | D130: CGL25022586 | E130: 45713 | F130: C0001 | G130: ARMOR MEXICO IMAGING SUPPLIES | H130: 31019.93 | I130: 0.206 | J130: ISRAEL
A131: NLD | B131: Febrero | C131: 2-002457 | D131: CGL25022572 | E131: 45713 | F131: C0001 | G131: ARMOR MEXICO IMAGING SUPPLIES | H131: 2982.36 | I131: 0.464 | J131: JESSICA
A132: VER | B132: Febrero | C132: 1-002458 | D132: CGL25022569 | E132: 45713 | F132: C0004 | G132: NAPS-GUANAJUATO AMERICAN BOA | H132: 42337.5 | I132: 0.405 | J132: ELIAS
A133: NLD | B133: Febrero | C133: 2-002459 | D133: CGL25022552 | E133: 45713 | F133: C0081 | G133: JOINT PRODUCTION BLACK SMITH | H133: 22000 | I133: 0.4 | J133: ALONSO
A134: NLD | B134: Febrero | C134: 2-002460 | D134: CGL25022603 | E134: 45714 | F134: C0001 | G134: ARMOR MEXICO IMAGING SUPPLIES | H134: 42268.96 | I134: 0.437 | J134: JESSICA
A135: NLD | B135: Febrero | C135: 2-002461 | D135: CGL25022597 | E135: 45714 | F135: C0081 | G135: JOINT PRODUCTION BLACK SMITH | H135: 22000 | I135: 0.447 | J135: ALONSO
A136: NLD | B136: Febrero | C136: 2-002462 | D136: CGL25022596 | E136: 45714 | F136: C0081 | G136: JOINT PRODUCTION BLACK SMITH | H136: 22000 | I136: 0.447 | J136: ALONSO
...

Sheet ACT2025
A1: OFICINA | B1: MES | C1: FACTURA | D1: TRAFICO | E1: FECHA | F1: CLIENTE | G1: CLIENTE NOMBRE | H1: IMPORTE | I1: PROFIT | J1: EJECUTIVO | K1: T OPERACIÓN
A2: NLD | B2: Enero | C2: 2-002317 | D2: CGL24122402 | E2: 45660 | F2: C0001 | G2: ARMOR MEXICO IMAGING SUPPLIES | H2: 16362.29 | I2: 0.423 | J2: JESSICA
A3: NLD | B3: Enero | C3: 2-002318 | D3: CGL24122374 | E3: 45660 | F3: C0001 | G3: ARMOR MEXICO IMAGING SUPPLIES | H3: 17562.29 | I3: 0.449 | J3: JESSICA
A4: VER | B4: Enero | C4: 1-002319 | D4: CGL24112354 | E4: 45660 | F4: C0001 | G4: ARMOR MEXICO IMAGING SUPPLIES | H4: 112970.32 | I4: 0.284 | J4: ISRAEL
A5: VER | B5: Enero | C5: 1-002320 | D5: CGL24122437 | E5: 45660 | F5: C0001 | G5: ARMOR MEXICO IMAGING SUPPLIES | H5: 3540 | I5: 0.259 | J5: ISRAEL
A6: NLD | B6: Enero | C6: 2-002321 | D6: CGL24122431 | E6: 45660 | F6: C0001 | G6: ARMOR MEXICO IMAGING SUPPLIES | H6: 2928.25 | I6: 0.59 | J6: JESSICA
A7: NLD | B7: Enero | C7: 2-002322 | D7: CGL24122391 | E7: 45660 | F7: C0001 | G7: ARMOR MEXICO IMAGING SUPPLIES | H7: 16361.73 | I7: 0.423 | J7: JESSICA
A8: VER | B8: Enero | C8: 1-002323 | D8: CGL24122418 | E8: 45660 | F8: C0001 | G8: ARMOR MEXICO IMAGING SUPPLIES | H8: 10620 | I8: 0.259 | J8: ISRAEL
A9: VER | B9: Enero | C9: 1-002324 | D9: CGL24112348 | E9: 45660 | F9: C0001 | G9: ARMOR MEXICO IMAGING SUPPLIES | H9: 79824.55 | I9: 0.225 | J9: ISRAEL
A10: NLD | B10: Enero | C10: 2-002325 | D10: CGL24122383 | E10: 45660 | F10: C0002 | G10: NAPS-GUANAJUATO CAM | H10: 6908.32 | I10: 0.551 | J10: NALLELY
A11: VER | B11: Enero | C11: 1-002326 | D11: CGL24082033 | E11: 45665 | F11: C0067 | G11: ND AUTOMOTIVE SYSTEMS MEXICO | H11: 0.01 | I11: 0 | J11: ALONSO
A12: VER | B12: Enero | C12: 1-002327 | D12: CGL24122395 | E12: 45666 | F12: C0001 | G12: ARMOR MEXICO IMAGING SUPPLIES | H12: 106812.52 | I12: 0.308 | J12: ISRAEL
A13: VER | B13: Enero | C13: 1-002328 | D13: CGL24122396 | E13: 45666 | F13: C0001 | G13: ARMOR MEXICO IMAGING SUPPLIES | H13: 84790.76 | I13: 0.293 | J13: ISRAEL
... A72: NLD | B72: Enero | C72: 2-002357 | D72: CGL24122435 | E72: 45680 | F72: C0084 | G72: JOINT PRODUCTION TECTRAN | H72: 140301.7 | I72: 0.175 | J72: ELIAS
A73: VER | B73: Enero | C73: 1-002358 | D73: CGL24122430 | E73: 45681 | F73: C0089 | G73: CHEMICAL COLOR DE MEXICO | H73: 83820.573 | I73: 0.346 | J73: ELIAS | K73: M
A74: VER | B74: Enero | C74: 1-002360 | D74: CGL24122432 | E74: 45681 | F74: C0001 | G74: ARMOR MEXICO IMAGING SUPPLIES | H74: 114208.08 | I74: 0.271 | J74: ISRAEL
A75: NLD | B75: Enero | C75: 2-002380 | D75: CGL25012470 | E75: 45687 | F75: C0084 | G75: JOINT PRODUCTION TECTRAN | H75: 125977.16 | I75: 0.205 | J75: ELIAS
A76: VER | B76: Enero | C76: 1-002381 | D76: CGL24122397 | E76: 45687 | F76: C0067 | G76: ND AUTOMOTIVE SYSTEMS MEXICO | H76: 7712.8875 | I76: 0.3 | J76: ALONSO
A77: VER | B77: Enero | C77: 1-002382 | D77: CGL24071864 | E77: 45687 | F77: C0067 | G77: ND AUTOMOTIVE SYSTEMS MEXICO | H77: 5141.925 | I77: 0.232 | J77: ALONSO
A78: VER | B78: Enero | C78: 1-002387 | D78: CGL25012469 | E78: 45688 | F78: C0090 | G78: INVICONT OÜ | H78: 1230867.4 | I78: -0.364 | J78: JESUS
A79: VER | B79: Febrero | C79: 1-002395 | D79: CGL24122432 | E79: 45694 | F79: C0001 | G79: ARMOR MEXICO IMAGING SUPPLIES | H79: 107360.24 | I79: 0.271 | J79: ISRAEL
A80: VER | B80: Febrero | C80: 1-002396 | D80: CGL25012475 | E80: 45694 | F80: C0001 | G80: ARMOR MEXICO IMAGING SUPPLIES | H80: 73868.29 | I80: 0.288 | J80: ISRAEL
A81: VER | B81: Febrero | C81: 1-002397 | D81: CGL25012515 | E81: 45694 | F81: C0069 | G81: JOINT PRODUCTION HONOR | H81: 13293.3 | I81: 0.414 | J81: ALONSO
A82: VER | B82: Febrero | C82: 1-002399 | D82: CGL25012513 | E82: 45694 | F82: C0004 | G82: NAPS-GUANAJUATO AMERICAN BOA | H82: 143742.45 | I82: 0.361 | J82: ELIAS
A83: NLD | B83: Febrero | C83: 2-002401 | D83: CGL25012522 | E83: 45695 | F83: C0001 | G83: ARMOR MEXICO IMAGING SUPPLIES | H83: 26000.04 | I83: 0.386 | J83: JESSICA
A84: NLD | B84: Febrero | C84: 2-002402 | D84: CGL25012464 | E84: 45695 | F84: C0069 | G84: JOINT PRODUCTION HONOR | H84: 15295.72 | I84: 0.856 | J84: JESSICA
A85: VER | B85: Febrero | C85: 1-002403 | D85: CGL25012501 | E85: 45699 | F85: C0084 | G85: JOINT PRODUCTION TECTRAN | H85: 21320.23 | I85: 0.259 | J85: ELIAS
... A124: NLD | B124: Febrero | C124: 2-002449 | D124: CGL25022563 | E124: 45708 | F124: C0002 | G124: NAPS-GUANAJUATO CAM | H124: 8047.47 | I124: 0.64 | J124: NALLELY
A125: VER | B125: Febrero | C125: 1-002450 | D125: CGL24122430 | E125: 45709 | F125: C0089 | G125: CHEMICAL COLOR DE MEXICO | H125: 95976 | I125: 0.346 | J125: ELIAS | K125: M
A126: VER | B126: Febrero | C126: 1-002451 | D126: CGL24122430 | E126: 45709 | F126: C0089 | G126: CHEMICAL COLOR DE MEXICO | H126: 1333 | I126: 0.346 | J126: ELIAS | K126: M
A127: NLD | B127: Febrero | C127: 2-002452 | D127: CGL25022554 | E127: 45709 | F127: C0002 | G127: NAPS-GUANAJUATO CAM | H127: 4133.86 | I127: 0.565 | J127: NALLELY
A128: NLD | B128: Febrero | C128: 2-002453 | D128: CGL25012447 | E128: 45709 | F128: C0002 | G128: NAPS-GUANAJUATO CAM | H128: 20348.24 | I128: 0.661 | J128: NALLELY
A129: NLD | B129: Febrero | C129: 2-002455 | D129: CGL25022581 | E129: 45712 | F129: C0001 | G129: ARMOR MEXICO IMAGING SUPPLIES | H129: 41061.64 | I129: 0.35 | J129: JESSICA
A130: VER | B130: Febrero | C130: 1-002456 | D130: CGL25022586 | E130: 45713 | F130: C0001 | G130: ARMOR MEXICO IMAGING SUPPLIES | H130: 31019.93 | I130: 0.206 | J130: ISRAEL
A131: NLD | B131: Febrero | C131: 2-002457 | D131: CGL25022572 | E131: 45713 | F131: C0001 | G131: ARMOR MEXICO IMAGING SUPPLIES | H131: 2982.36 | I131: 0.464 | J131: JESSICA
A132: VER | B132: Febrero | C132: 1-002458 | D132: CGL25022569 | E132: 45713 | F132: C0004 | G132: NAPS-GUANAJUATO AMERICAN BOA | H132: 42337.5 | I132: 0.405 | J132: ELIAS
A133: NLD | B133: Febrero | C133: 2-002459 | D133: CGL25022552 | E133: 45713 | F133: C0081 | G133: JOINT PRODUCTION BLACK SMITH | H133: 22000 | I133: 0.4 | J133: ALONSO
A134: NLD | B134: Febrero | C134: 2-002460 | D134: CGL25022603 | E134: 45714 | F134: C0001 | G134: ARMOR MEXICO IMAGING SUPPLIES | H134: 42268.96 | I134: 0.437 | J134: JESSICA
A135: NLD | B135: Febrero | C135: 2-002461 | D135: CGL25022597 | E135: 45714 | F135: C0081 | G135: JOINT PRODUCTION BLACK SMITH | H135: 22000 | I135: 0.447 | J135: ALONSO
A136: NLD | B136: Febrero | C136: 2-002462 | D136: CGL25022596 | E136: 45714 | F136: C0081 | G136: JOINT PRODUCTION BLACK SMITH | H136: 22000 | I136: 0.447 | J136: ALONSO
...

Sheet ANALISIS 
A1: OFICINA | B1: MES | C1: FACTURA | D1: TRAFICO | E1: FECHA | F1: CLIENTE | G1: CLIENTE NOMBRE | H1: IMPORTE | I1: PROFIT | J1: EJECUTIVO | K1: T OPERACIÓN
A2: NLD | B2: Enero | C2: 2-002317 | D2: CGL24122402 | E2: 45660 | F2: C0001 | G2: ARMOR MEXICO IMAGING SUPPLIES | H2: 16362.29 | I2: 0.423 | J2: JESSICA
A3: NLD | B3: Enero | C3: 2-002318 | D3: CGL24122374 | E3: 45660 | F3: C0001 | G3: ARMOR MEXICO IMAGING SUPPLIES | H3: 17562.29 | I3: 0.449 | J3: JESSICA
A4: VER | B4: Enero | C4: 1-002319 | D4: CGL24112354 | E4: 45660 | F4: C0001 | G4: ARMOR MEXICO IMAGING SUPPLIES | H4: 112970.32 | I4: 0.284 | J4: ISRAEL
A5: VER | B5: Enero | C5: 1-002320 | D5: CGL24122437 | E5: 45660 | F5: C0001 | G5: ARMOR MEXICO IMAGING SUPPLIES | H5: 3540 | I5: 0.259 | J5: ISRAEL
A6: NLD | B6: Enero | C6: 2-002321 | D6: CGL24122431 | E6: 45660 | F6: C0001 | G6: ARMOR MEXICO IMAGING SUPPLIES | H6: 2928.25 | I6: 0.59 | J6: JESSICA
A7: NLD | B7: Enero | C7: 2-002322 | D7: CGL24122391 | E7: 45660 | F7: C0001 | G7: ARMOR MEXICO IMAGING SUPPLIES | H7: 16361.73 | I7: 0.423 | J7: JESSICA
A8: VER | B8: Enero | C8: 1-002323 | D8: CGL24122418 | E8: 45660 | F8: C0001 | G8: ARMOR MEXICO IMAGING SUPPLIES | H8: 10620 | I8: 0.259 | J8: ISRAEL
A9: VER | B9: Enero | C9: 1-002324 | D9: CGL24112348 | E9: 45660 | F9: C0001 | G9: ARMOR MEXICO IMAGING SUPPLIES | H9: 79824.55 | I9: 0.225 | J9: ISRAEL
A10: NLD | B10: Enero | C10: 2-002325 | D10: CGL24122383 | E10: 45660 | F10: C0002 | G10: NAPS-GUANAJUATO CAM | H10: 6908.32 | I10: 0.551 | J10: NALLELY
A11: VER | B11: Enero | C11: 1-002326 | D11: CGL24082033 | E11: 45665 | F11: C0067 | G11: ND AUTOMOTIVE SYSTEMS MEXICO | H11: 0.01 | I11: 0 | J11: ALONSO
A12: VER | B12: Enero | C12: 1-002327 | D12: CGL24122395 | E12: 45666 | F12: C0001 | G12: ARMOR MEXICO IMAGING SUPPLIES | H12: 106812.52 | I12: 0.308 | J12: ISRAEL
A13: VER | B13: Enero | C13: 1-002328 | D13: CGL24122396 | E13: 45666 | F13: C0001 | G13: ARMOR MEXICO IMAGING SUPPLIES | H13: 84790.76 | I13: 0.293 | J13: ISRAEL
... A72: NLD | B72: Enero | C72: 2-002357 | D72: CGL24122435 | E72: 45680 | F72: C0084 | G72: JOINT PRODUCTION TECTRAN | H72: 140301.7 | I72: 0.175 | J72: ELIAS
A73: VER | B73: Enero | C73: 1-002358 | D73: CGL24122430 | E73: 45681 | F73: C0089 | G73: CHEMICAL COLOR DE MEXICO | H73: 83820.573 | I73: 0.346 | J73: ELIAS | K73: M
A74: VER | B74: Enero | C74: 1-002360 | D74: CGL24122432 | E74: 45681 | F74: C0001 | G74: ARMOR MEXICO IMAGING SUPPLIES | H74: 114208.08 | I74: 0.271 | J74: ISRAEL
A75: NLD | B75: Enero | C75: 2-002380 | D75: CGL25012470 | E75: 45687 | F75: C0084 | G75: JOINT PRODUCTION TECTRAN | H75: 125977.16 | I75: 0.205 | J75: ELIAS
A76: VER | B76: Enero | C76: 1-002381 | D76: CGL24122397 | E76: 45687 | F76: C0067 | G76: ND AUTOMOTIVE SYSTEMS MEXICO | H76: 7712.8875 | I76: 0.3 | J76: ALONSO
A77: VER | B77: Enero | C77: 1-002382 | D77: CGL24071864 | E77: 45687 | F77: C0067 | G77: ND AUTOMOTIVE SYSTEMS MEXICO | H77: 5141.925 | I77: 0.232 | J77: ALONSO
A78: VER | B78: Enero | C78: 1-002387 | D78: CGL25012469 | E78: 45688 | F78: C0090 | G78: INVICONT OÜ | H78: 1230867.4 | I78: 0.415 | J78: JESUS
A79: VER | B79: Febrero | C79: 1-002395 | D79: CGL24122432 | E79: 45694 | F79: C0001 | G79: ARMOR MEXICO IMAGING SUPPLIES | H79: 107360.24 | I79: 0.271 | J79: ISRAEL
A80: VER | B80: Febrero | C80: 1-002396 | D80: CGL25012475 | E80: 45694 | F80: C0001 | G80: ARMOR MEXICO IMAGING SUPPLIES | H80: 73868.29 | I80: 0.288 | J80: ISRAEL
A81: VER | B81: Febrero | C81: 1-002397 | D81: CGL25012515 | E81: 45694 | F81: C0069 | G81: JOINT PRODUCTION HONOR | H81: 13293.3 | I81: 0.414 | J81: ALONSO
A82: VER | B82: Febrero | C82: 1-002399 | D82: CGL25012513 | E82: 45694 | F82: C0004 | G82: NAPS-GUANAJUATO AMERICAN BOA | H82: 143742.45 | I82: 0.361 | J82: ELIAS
A83: NLD | B83: Febrero | C83: 2-002401 | D83: CGL25012522 | E83: 45695 | F83: C0001 | G83: ARMOR MEXICO IMAGING SUPPLIES | H83: 26000.04 | I83: 0.386 | J83: JESSICA
A84: NLD | B84: Febrero | C84: 2-002402 | D84: CGL25012464 | E84: 45695 | F84: C0069 | G84: JOINT PRODUCTION HONOR | H84: 15295.72 | I84: 0.856 | J84: JESSICA
A85: VER | B85: Febrero | C85: 1-002403 | D85: CGL25012501 | E85: 45699 | F85: C0084 | G85: JOINT PRODUCTION TECTRAN | H85: 21320.23 | I85: 0.259 | J85: ELIAS
... A124: NLD | B124: Febrero | C124: 2-002449 | D124: CGL25022563 | E124: 45708 | F124: C0002 | G124: NAPS-GUANAJUATO CAM | H124: 8047.47 | I124: 0.64 | J124: NALLELY
A125: VER | B125: Febrero | C125: 1-002450 | D125: CGL24122430 | E125: 45709 | F125: C0089 | G125: CHEMICAL COLOR DE MEXICO | H125: 95976 | I125: 0.346 | J125: ELIAS | K125: M
A126: VER | B126: Febrero | C126: 1-002451 | D126: CGL24122430 | E126: 45709 | F126: C0089 | G126: CHEMICAL COLOR DE MEXICO | H126: 1333 | I126: 0.346 | J126: ELIAS | K126: M
A127: NLD | B127: Febrero | C127: 2-002452 | D127: CGL25022554 | E127: 45709 | F127: C0002 | G127: NAPS-GUANAJUATO CAM | H127: 4133.86 | I127: 0.565 | J127: NALLELY
A128: NLD | B128: Febrero | C128: 2-002453 | D128: CGL25012447 | E128: 45709 | F128: C0002 | G128: NAPS-GUANAJUATO CAM | H128: 20348.24 | I128: 0.661 | J128: NALLELY
A129: NLD | B129: Febrero | C129: 2-002455 | D129: CGL25022581 | E129: 45712 | F129: C0001 | G129: ARMOR MEXICO IMAGING SUPPLIES | H129: 41061.64 | I129: 0.35 | J129: JESSICA
A130: VER | B130: Febrero | C130: 1-002456 | D130: CGL25022586 | E130: 45713 | F130: C0001 | G130: ARMOR MEXICO IMAGING SUPPLIES | H130: 31019.93 | I130: 0.206 | J130: ISRAEL
A131: NLD | B131: Febrero | C131: 2-002457 | D131: CGL25022572 | E131: 45713 | F131: C0001 | G131: ARMOR MEXICO IMAGING SUPPLIES | H131: 2982.36 | I131: 0.464 | J131: JESSICA
A132: VER | B132: Febrero | C132: 1-002458 | D132: CGL25022569 | E132: 45713 | F132: C0004 | G132: NAPS-GUANAJUATO AMERICAN BOA | H132: 42337.5 | I132: 0.405 | J132: ELIAS
A133: NLD | B133: Febrero | C133: 2-002459 | D133: CGL25022552 | E133: 45713 | F133: C0081 | G133: JOINT PRODUCTION BLACK SMITH | H133: 22000 | I133: 0.4 | J133: ALONSO
A134: NLD | B134: Febrero | C134: 2-002460 | D134: CGL25022603 | E134: 45714 | F134: C0001 | G134: ARMOR MEXICO IMAGING SUPPLIES | H134: 42268.96 | I134: 0.437 | J134: JESSICA
A135: NLD | B135: Febrero | C135: 2-002461 | D135: CGL25022597 | E135: 45714 | F135: C0081 | G135: JOINT PRODUCTION BLACK SMITH | H135: 22000 | I135: 0.447 | J135: ALONSO
A136: NLD | B136: Febrero | C136: 2-002462 | D136: CGL25022596 | E136: 45714 | F136: C0081 | G136: JOINT PRODUCTION BLACK SMITH | H136: 22000 | I136: 0.447 | J136: ALONSO
...

Sheet Mensual por Cliente 2025 (2)
B2: CORE GLOBAL LOGISTICS MANAGEMENT, S.A. DE C.V.
B3: FACTURACIÓN MENSUAL POR CLIENTE
B4: =+'Acumulado 2025'!B7 -> FACTURACIÓN ACUMULADA DEL 1o DE ENERO AL 31 de Diciembre 2025
B5: NOMBRE DEL CLIENTE | C5: ENERO | D5: FEBRERO | E5: MARZO | F5: ABRIL | G5: MAYO | H5: JUNIO | I5: JULIO | J5: AGOSTO | K5: SEPTIEMBRE | L5: OCTUBRE | M5: NOVIEMBRE | N5: DICIEMBRE | O5: TOTAL
B6: JOINT PRODUCTION HONOR | E6: 68165.36 | F6: 305529.43 | G6: 2748441.5 | H6: 2468042.6 | I6: 981970.54 | J6: 1750208 | K6: 363807.05 | L6: 77438.97 | M6: 1760615.2 | N6: =1855140.04-157074.9 -> 1698065.1 | O6: =+SUM(C6:N6) -> 12222284
B7: NAPS-GUANAJUATO AMERICAN BOA | C7: 270193.3 | D7: 463048.06 | E7: 743676.61 | F7: 658055.37 | G7: 1535423.1 | H7: 1349163.2 | I7: 1632113.9 | J7: 541275.49 | K7: 568841.59 | L7: 387674.04 | M7: 492880.93 | N7: =358921.84+157074.9 -> 515996.74 | O7: =+SUM(C7:N7) -> 9158342.3
B8: ARMOR MEXICO IMAGING SUPPLIES | C8: 457339.78 | D8: 711895.55 | E8: 614420.98 | F8: 307536.36 | G8: 776104.41 | H8: 453435.68 | I8: 743519.76 | J8: 877319.16 | K8: 897446.77 | L8: 699117.06 | M8: 733715.51 | N8: 202792.9 | O8: =+SUM(C8:N8) -> 7474643.9
B9: NAPS-GUANAJUATO CAM | C9: 271551.74 | D9: 208533.3 | E9: 227575.7 | F9: 309784.13 | G9: 223935.22 | H9: 265068.56 | I9: 224167.66 | J9: 246719.76 | K9: 233633.09 | L9: 337448.47 | M9: 336241.75 | N9: 289920.8 | O9: =+SUM(C9:N9) -> 3174580.2
B10: NAPS-GUANAJUATO WARREN | C10: 12958.46 | D10: 34729.52 | E10: 1281473.3 | F10: 17005 | O10: =+SUM(C10:N10) -> 1346166.3
B11: ND AUTOMOTIVE SYSTEMS MEXICO | G11: 71891.915 | H11: 247367.59 | I11: 181571.73 | K11: 662865.27 | L11: 4917.425 | M11: 639098.45 | N11: 207087.13 | O11: =+SUM(C11:N11) -> 2014799.5
B12: NOVANDI | D12: 60995.008 | E12: 130940 | F12: 868840.01 | G12: 56406.8 | I12: 12319.42 | O12: =+SUM(C12:N12) -> 1129501.2
B13: COLEP | C13: 19000 | D13: 1049776.7 | O13: =+SUM(C13:N13) -> 1068776.7
B14: MEGALUMINIO SERVICIOS | C14: 72345.397 | D14: 103304 | F14: 59426.151 | G14: 124529.54 | I14: 148520.51 | J14: 102670 | K14: 125503.1 | M14: 14178 | N14: 102993.68 | O14: =+SUM(C14:N14) -> 853470.38
B15: ALMACENES GENERALES VALENCIA SL | C15: 365803.99 | D15: 41630.768 | G15: 188091.6 | J15: 221867.34 | K15: 6407.8271 | O15: =+SUM(C15:N15) -> 823801.53
B16: JOINT PRODUCTION TECTRAN | L16: 103607.64 | M16: 260500.39 | N16: 386991.36 | O16: =+SUM(C16:N16) -> 751099.39
B17: MAV INGENIEROS CONSULTORES Y ASOCIADOS | D17: 6866.42 | F17: 121454.18 | H17: 268049.16 | O17: =+SUM(C17:N17) -> 396369.76
