Workbook

Sheet ENE MXN
A1: SERIE | B1: FACTURA | C1: TRAFICO | D1: FECHA | E1: CLIENTE | F1: CLIENTE NOMBRE | G1: COMPROBADOS | H1: COMPLEMENTARIOS | I1: IVA | J1: SUBTOTAL | K1: ANTICIPO | L1: TOTAL | M1: MONEDA | P1: DOCUMENTACION, ALMACENAJES Y MANIOBRAS ( TER) | Q1: IMPUESTOS ADUANALES (TER) | S1: HONORARIOS | T1: RECONOCIMIENTO ADUANERO | U1: REVALIDACION GUIA / BOL | V1: SERVICIOS COMPLEMENTARIOS | W1: MANIOBRAS | X1: ALMACENAJES | Y1: SERVICIOS LOGISTICOS | Z1: CONSOLIDACION DE ENTRADAS | AA1: SERVICIO EXTRAORDINARIO | AB1: CERTIFICADO DE ORIGEN | AC1: REPARACION DE DAÑOS DE CONTENEDOR | AD1: LIMPIEZA DE CONTENEDOR | AE1: CUOTA | AF1: DEMORAS | AG1: LIBERACION DE DOCUMENTOS | AK1: MXN | AL1: USD | AM1: TOTAL | AN1: PORCENTAJE
B2: 2-002317 | C2: CGL24122402 | D2: 45660 | E2: C0001 | F2: ARMOR MEXICO IMAGING SUPPLIES | G2: 0 | H2: 16362.29 | I2: 2617.96 | J2: =SUM(G2:I2) -> 18980.25 | K2: 0 | L2: =+J2-K2 -> 18980.25 | M2: MXN | Q2: 0 | S2: 4028.96 | T2: 0 | U2: 0 | V2: 0 | W2: 0 | X2: 0 | Y2: 12333.33 | Z2: 0 | AA2: 0 | AB2: 0 | AC2: 0 | AD2: 0 | AE2: 0 | AF2: 0 | AG2: 0 | AH2: =+SUM(S2:AG2)-H2 -> 0 | AJ2: HONORARIOS | AK2: =+S74 -> 280300.43 | AL2: =+'ENE USD '!AE19 -> 508379.54 | AM2: =SUM(AK2:AL2) -> 788679.97 | AN2: =+AM2/AM24 -> 0.20841218
B3: 2-002318 | C3: CGL24122374 | D3: 45660 | E3: C0001 | F3: ARMOR MEXICO IMAGING SUPPLIES | G3: 0 | H3: 17562.29 | I3: 2809.96 | J3: =SUM(G3:I3) -> 20372.25 | K3: 0 | L3: =+J3-K3 -> 20372.25 | M3: MXN | Q3: 0 | S3: 4028.96 | T3: 0 | U3: 0 | V3: 0 | W3: 1200 | X3: 0 | Y3: 12333.33 | Z3: 0 | AA3: 0 | AB3: 0 | AC3: 0 | AD3: 0 | AE3: 0 | AF3: 0 | AG3: 0 | AH3: =+SUM(S3:AG3)-H3 -> 0 | AJ3: RECONOCIMIENTO ADUANERO | AK3: =+T74 -> 4191 | AM3: =SUM(AK3:AL3) -> 4191 | AN3: =+AM3/AM24 -> 0.0011074903
B4: 1-002319 | C4: CGL24112354 | D4: 45660 | E4: C0001 | F4: ARMOR MEXICO IMAGING SUPPLIES | G4: 0 | H4: 112970.32 | I4: 18075.25 | J4: =SUM(G4:I4) -> 131045.57 | K4: 0 | L4: =+J4-K4 -> 131045.57 | M4: MXN | Q4: 0 | S4: 6058.89 | T4: 0 | U4: 0 | V4: 0 | W4: 29072.04 | X4: 8504.39 | Y4: 69335 | Z4: 0 | AA4: 0 | AB4: 0 | AC4: 0 | AD4: 0 | AE4: 0 | AF4: 0 | AG4: 0 | AH4: =+SUM(S4:AG4)-H4 -> 0 | AJ4: REVALIDACION GUIA / BOL | AK4: =+U74 -> 7846.42 | AM4: =SUM(AK4:AL4) -> 7846.42 | AN4: =+AM4/AM24 -> 0.0020734513
B5: 1-002320 | C5: CGL24122437 | D5: 45660 | E5: C0001 | F5: ARMOR MEXICO IMAGING SUPPLIES | G5: 0 | H5: 3540 | I5: 566.4 | J5: =SUM(G5:I5) -> 4106.4 | K5: 0 | L5: =+J5-K5 -> 4106.4 | M5: MXN | Q5: 0 | S5: 0 | T5: 0 | U5: 0 | V5: 0 | W5: 0 | X5: 0 | Y5: 0 | Z5: 0 | AA5: 0 | AB5: 3540 | AC5: 0 | AD5: 0 | AE5: 0 | AF5: 0 | AG5: 0 | AH5: =+SUM(S5:AG5)-H5 -> 0 | AJ5: SERVICIOS COMPLEMENTARIOS | AK5: =+V74 -> 12350 | AM5: =SUM(AK5:AL5) -> 12350 | AN5: =+AM5/AM24 -> 0.0032635423
B6: 2-002321 | C6: CGL24122431 | D6: 45660 | E6: C0001 | F6: ARMOR MEXICO IMAGING SUPPLIES | G6: 0 | H6: 2928.25 | I6: 468.52 | J6: =SUM(G6:I6) -> 3396.77 | K6: 0 | L6: =+J6-K6 -> 3396.77 | M6: MXN | Q6: 0 | S6: 2928.25 | T6: 0 | U6: 0 | V6: 0 | W6: 0 | X6: 0 | Y6: 0 | Z6: 0 | AA6: 0 | AB6: 0 | AC6: 0 | AD6: 0 | AE6: 0 | AF6: 0 | AG6: 0 | AH6: =+SUM(S6:AG6)-H6 -> 0 | AJ6: MANIOBRAS | AK6: =+W74 -> 513327.14 | AL6: =+'ENE USD '!AC19 -> 715330.51 | AM6: =SUM(AK6:AL6) -> 1228657.6 | AN6: =+AM6/AM24 -> 0.32467823
B7: 2-002322 | C7: CGL24122391 | D7: 45660 | E7: C0001 | F7: ARMOR MEXICO IMAGING SUPPLIES | G7: 0 | H7: 16361.73 | I7: 2617.87 | J7: =SUM(G7:I7) -> 18979.6 | K7: 0 | L7: =+J7-K7 -> 18979.6 | M7: MXN | Q7: 0 | S7: 4028.4 | T7: 0 | U7: 0 | V7: 0 | W7: 0 | X7: 0 | Y7: 12333.33 | Z7: 0 | AA7: 0 | AB7: 0 | AC7: 0 | AD7: 0 | AE7: 0 | AF7: 0 | AG7: 0 | AH7: =+SUM(S7:AG7)-H7 -> 0 | AJ7: ALMACENAJES | AK7: =+X74 -> 153351.11 | AM7: =SUM(AK7:AL7) -> 153351.11 | AN7: =+AM7/AM24 -> 0.040523711
B8: 1-002323 | C8: CGL24122418 | D8: 45660 | E8: C0001 | F8: ARMOR MEXICO IMAGING SUPPLIES | G8: 0 | H8: 10620 | I8: 1699.2 | J8: =SUM(G8:I8) -> 12319.2 | K8: 0 | L8: =+J8-K8 -> 12319.2 | M8: MXN | Q8: 0 | S8: 0 | T8: 0 | U8: 0 | V8: 0 | W8: 0 | X8: 0 | Y8: 0 | Z8: 0 | AA8: 0 | AB8: 10620 | AC8: 0 | AD8: 0 | AE8: 0 | AF8: 0 | AG8: 0 | AH8: =+SUM(S8:AG8)-H8 -> 0 | AJ8: SERVICIOS LOGISTICOS | AK8: =+Y74 -> 957587.41 | AL8: =+'ENE USD '!AB19 -> 465070.83 | AM8: =SUM(AK8:AL8) -> 1422658.2 | AN8: =+AM8/AM24 -> 0.37594375
B9: 1-002324 | C9: CGL24112348 | D9: 45660 | E9: C0001 | F9: ARMOR MEXICO IMAGING SUPPLIES | G9: 0 | H9: 79824.55 | I9: 12771.93 | J9: =SUM(G9:I9) -> 92596.48 | K9: 0 | L9: =+J9-K9 -> 92596.48 | M9: MXN | Q9: 0 | S9: 6074.55 | T9: 0 | U9: 0 | V9: 0 | W9: 25750 | X9: 0 | Y9: 48000 | Z9: 0 | AA9: 0 | AB9: 0 | AC9: 0 | AD9: 0 | AE9: 0 | AF9: 0 | AG9: 0 | AH9: =+SUM(S9:AG9)-H9 -> 0 | AJ9: CONSOLIDACION DE ENTRADAS | AK9: =+Z74 -> 20112.16 | AM9: =SUM(AK9:AL9) -> 20112.16 | AN9: =+AM9/AM24 -> 0.0053147275
B10: 2-002325 | C10: CGL24122383 | D10: 45660 | E10: C0002 | F10: NAPS-GUANAJUATO CAM | G10: 336 | H10: 6908.32 | I10: 1105.33 | J10: =SUM(G10:I10) -> 8349.65 | K10: 8349.65 | L10: =+J10-K10 -> 0 | M10: MXN | Q10: 336 | S10: 2958.32 | T10: 0 | U10: 0 | V10: 0 | W10: 0 | X10: 0 | Y10: 3950 | Z10: 0 | AA10: 0 | AB10: 0 | AC10: 0 | AD10: 0 | AE10: 0 | AF10: 0 | AG10: 0 | AH10: =+SUM(S10:AG10)-H10 -> 0 | AJ10: SERVICIO EXTRAORDINARIO | AK10: =+AA74 -> 1800 | AM10: =SUM(AK10:AL10) -> 1800 | AN10: =+AM10/AM24 -> 0.00047565798
B11: 1-002326 | C11: CGL24082033 | D11: 45665 | E11: C0067 | F11: ND AUTOMOTIVE SYSTEMS MEXICO | G11: 761 | H11: 0.01 | I11: 0 | J11: =SUM(G11:I11) -> 761.01 | K11: 0 | L11: =+J11-K11 -> 761.01 | M11: MXN | Q11: 761 | S11: 0.01 | T11: 0 | U11: 0 | V11: 0 | W11: 0 | X11: 0 | Y11: 0 | Z11: 0 | AA11: 0 | AB11: 0 | AC11: 0 | AD11: 0 | AE11: 0 | AF11: 0 | AG11: 0 | AH11: =+SUM(S11:AG11)-H11 -> 0 | AJ11: CERTIFICADO DE ORIGEN | AK11: =+AB74 -> 17700 | AM11: =SUM(AK11:AL11) -> 17700 | AN11: =+AM11/AM24 -> 0.0046773035
B12: 1-002327 | C12: CGL24122395 | D12: 45666 | E12: C0001 | F12: ARMOR MEXICO IMAGING SUPPLIES | G12: 0 | H12: 106812.52 | I12: 17090 | J12: =SUM(G12:I12) -> 123902.52 | K12: 0 | L12: =+J12-K12 -> 123902.52 | M12: MXN | Q12: 0 | S12: 6070.89 | T12: 0 | U12: 0 | V12: 0 | W12: 29072.04 | X12: 5669.59 | Y12: 66000 | Z12: 0 | AA12: 0 | AB12: 0 | AC12: 0 | AD12: 0 | AE12: 0 | AF12: 0 | AG12: 0 | AH12: =+SUM(S12:AG12)-H12 -> 0 | AJ12: REPARACION DE DAÑOS DE CONTENEDOR | AK12: =+AC74 -> 1000 | AM12: =SUM(AK12:AL12) -> 1000 | AN12: =+AM12/AM24 -> 0.00026425444
B13: 1-002328 | C13: CGL24122396 | D13: 45666 | E13: C0001 | F13: ARMOR MEXICO IMAGING SUPPLIES | G13: 0 | H13: 84790.76 | I13: 13566.52 | J13: =SUM(G13:I13) -> 98357.28 | K13: 0 | L13: =+J13-K13 -> 98357.28 | M13: MXN | Q13: 0 | S13: 6132.06 | T13: 0 | U13: 0 | V13: 0 | W13: 25750 | X13: 6573.7 | Y13: 45335 | Z13: 0 | AA13: 0 | AB13: 0 | AC13: 1000 | AD13: 0 | AE13: 0 | AF13: 0 | AG13: 0 | AH13: =+SUM(S13:AG13)-H13 -> 0 | AJ13: LIMPIEZA DE CONTENEDOR | AK13: =+AD74 -> 0 | AM13: =SUM(AK13:AL13) -> 0 | AN13: =+AM13/AM24 -> 0
B14: 2-002329 | C14: CGL24122392 | D14: 45666 | E14: C0001 | F14: ARMOR MEXICO IMAGING SUPPLIES | G14: 0 | H14: 18579.25 | I14: 2972.68 | J14: =SUM(G14:I14) -> 21551.93 | K14: 0 | L14: =+J14-K14 -> 21551.93 | M14: MXN | Q14: 0 | S14: 4157.24 | T14: 0 | U14: 0 | V14: 0 | W14: 0 | X14: 0 | Y14: 14422.01 | Z14: 0 | AA14: 0 | AB14: 0 | AC14: 0 | AD14: 0 | AE14: 0 | AF14: 0 | AG14: 0 | AH14: =+SUM(S14:AG14)-H14 -> 0 | AJ14: LIBERACION DE DOCUMENTOS | AK14: =+AG74 -> 8902 | AL14: =+'ENE USD '!AD19 -> 10756.743 | AM14: =SUM(AK14:AL14) -> 19658.743 | AN14: =+AM14/AM24 -> 0.0051949099
B15: 1-002330 | C15: CGL24112312 | D15: 45666 | E15: C0069 | F15: JOINT PRODUCTION HONOR | G15: 180702 | H15: 205227.85 | I15: 32836.46 | J15: =SUM(G15:I15) -> 418766.31 | K15: 406517.64 | L15: =+J15-K15 -> 12248.67 | M15: MXN | Q15: 180702 | S15: 7350.23 | T15: 0 | U15: 0 | V15: 0 | W15: 93226.54 | X15: 104651.08 | Y15: 0 | Z15: 0 | AA15: 0 | AB15: 0 | AC15: 0 | AD15: 0 | AE15: 0 | AF15: 0 | AG15: 0 | AH15: =+SUM(S15:AG15)-H15 -> 0 | AJ15: DEMORAS | AK15: =+AF74 -> 44880 | AM15: =SUM(AK15:AL15) -> 44880 | AN15: =+AM15/AM24 -> 0.011859739
B16: 1-002331 | C16: CGL24122433 | D16: 45667 | E16: C0001 | F16: ARMOR MEXICO IMAGING SUPPLIES | G16: 0 | H16: 27182.81 | I16: 4349.25 | J16: =SUM(G16:I16) -> 31532.06 | K16: 0 | L16: =+J16-K16 -> 31532.06 | M16: MXN | Q16: 0 | S16: 4031.16 | T16: 0 | U16: 3500 | V16: 500 | W16: 9004.06 | X16: 1372.59 | Y16: 8775 | Z16: 0 | AA16: 0 | AB16: 0 | AC16: 0 | AD16: 0 | AE16: 0 | AF16: 0 | AG16: 0 | AH16: =+SUM(S16:AG16)-H16 -> 0 | AJ16: GASTOS EN DESTINO | AL16: =+'ENE USD '!AF19 -> 56526.293 | AM16: =SUM(AK16:AL16) -> 56526.293 | AN16: =+AM16/AM24 -> 0.014937324
B17: 1-002332 | C17: CGL24122379 | D17: 45670 | E17: C0069 | F17: JOINT PRODUCTION HONOR | G17: 761 | H17: 16728.86 | I17: 2676.62 | J17: =SUM(G17:I17) -> 20166.48 | K17: 20166.48 | L17: =+J17-K17 -> 0 | M17: MXN | Q17: 761 | S17: 7285.06 | T17: 0 | U17: 0 | V17: 0 | W17: 9443.8 | X17: 0 | Y17: 0 | Z17: 0 | AA17: 0 | AB17: 0 | AC17: 0 | AD17: 0 | AE17: 0 | AF17: 0 | AG17: 0 | AH17: =+SUM(S17:AG17)-H17 -> 0 | AJ17: CUOTA | AK17: =+AE74 -> 3277.5 | AL17: =+'ENE USD '!AG19 -> 1542.5775 | AM17: =SUM(AK17:AL17) -> 4820.0775 | AN17: =+AM17/AM24 -> 0.0012737269
B18: 2-002333 | C18: CGL24122390 | D18: 45670 | E18: C0002 | F18: NAPS-GUANAJUATO CAM | G18: 29608 | H18: 15835.71 | I18: 2533.72 | J18: =SUM(G18:I18) -> 47977.43 | K18: 54204.42 | L18: =+J18-K18 -> -6226.99 | M18: MXN | Q18: 29608 | S18: 4134.16 | T18: 0 | U18: 0 | V18: 0 | W18: 0 | X18: 0 | Y18: 3950 | Z18: 7751.55 | AA18: 0 | AB18: 0 | AC18: 0 | AD18: 0 | AE18: 0 | AF18: 0 | AG18: 0 | AH18: =+SUM(S18:AG18)-H18 -> 0 | AM18: =SUM(AK18:AL18) -> 0 | AN18: =+AM18/AM24 -> 0
B19: 1-002335 | C19: CGL24122417 | D19: 45670 | E19: C0067 | F19: ND AUTOMOTIVE SYSTEMS MEXICO | G19: 1192.68 | H19: 26279.86 | I19: 4204.78 | J19: =SUM(G19:I19) -> 31677.32 | K19: 0 | L19: =+J19-K19 -> 31677.32 | M19: MXN | P19: 1192.68 | Q19: 0 | S19: 6029.86 | T19: 0 | U19: 0 | V19: 0 | W19: 0 | X19: 0 | Y19: 20250 | Z19: 0 | AA19: 0 | AB19: 0 | AC19: 0 | AD19: 0 | AE19: 0 | AF19: 0 | AG19: 0 | AH19: =+SUM(S19:AG19)-H19 -> 0
B20: 2-002336 | C20: CGL24122414 | D20: 45671 | E20: C0002 | F20: NAPS-GUANAJUATO CAM | G20: 7626 | H20: 8006.14 | I20: 1280.98 | J20: =SUM(G20:I20) -> 16913.12 | K20: 16913.12 | L20: =+J20-K20 -> 0 | M20: MXN | Q20: 7626 | S20: 4056.14 | T20: 0 | U20: 0 | V20: 3950 | W20: 0 | X20: 0 | Y20: 0 | Z20: 0 | AA20: 0 | AB20: 0 | AC20: 0 | AD20: 0 | AE20: 0 | AF20: 0 | AG20: 0 | AH20: =+SUM(S20:AG20)-H20 -> 0
B21: 2-002337 | C21: CGL25012441 | D21: 45671 | E21: C0002 | F21: NAPS-GUANAJUATO CAM | G21: 781 | H21: 8013.9 | I21: 1282.22 | J21: =SUM(G21:I21) -> 10077.12 | K21: 10077.12 | L21: =+J21-K21 -> 0 | M21: MXN | Q21: 781 | S21: 4063.9 | T21: 0 | U21: 0 | V21: 0 | W21: 0 | X21: 0 | Y21: 3950 | Z21: 0 | AA21: 0 | AB21: 0 | AC21: 0 | AD21: 0 | AE21: 0 | AF21: 0 | AG21: 0 | AH21: =+SUM(S21:AG21)-H21 -> 0
B22: 2-002338 | C22: CGL25012442 | D22: 45671 | E22: C0002 | F22: NAPS-GUANAJUATO CAM | G22: 5735 | H22: 8008.72 | I22: 1281.4 | J22: =SUM(G22:I22) -> 15025.12 | K22: 15025.12 | L22: =+J22-K22 -> 0 | M22: MXN | Q22: 5735 | S22: 4058.72 | T22: 0 | U22: 0 | V22: 0 | W22: 0 | X22: 0 | Y22: 3950 | Z22: 0 | AA22: 0 | AB22: 0 | AC22: 0 | AD22: 0 | AE22: 0 | AF22: 0 | AG22: 0 | AH22: =+SUM(S22:AG22)-H22 -> 0
B23: 2-002339 | C23: CGL25012452 | D23: 45671 | E23: C0002 | F23: NAPS-GUANAJUATO CAM | G23: 781 | H23: 8013.9 | I23: 1282.22 | J23: =SUM(G23:I23) -> 10077.12 | K23: 10077.12 | L23: =+J23-K23 -> 0 | M23: MXN | Q23: 781 | S23: 4063.9 | T23: 0 | U23: 0 | V23: 0 | W23: 0 | X23: 0 | Y23: 3950 | Z23: 0 | AA23: 0 | AB23: 0 | AC23: 0 | AD23: 0 | AE23: 0 | AF23: 0 | AG23: 0 | AH23: =+SUM(S23:AG23)-H23 -> 0 | AK23: 0 | AM23: =SUM(AK23:AL23) -> 0 | AN23: =+AM23/AM24 -> 0
B24: 2-002340 | C24: CGL24122420 | D24: 45671 | E24: C0002 | F24: NAPS-GUANAJUATO CAM | G24: 1231 | H24: 12013.9 | I24: 1922.22 | J24: =SUM(G24:I24) -> 15167.12 | K24: 10526.12 | L24: =+J24-K24 -> 4641 | M24: MXN | Q24: 1231 | S24: 4063.9 | T24: 1500 | U24: 0 | V24: 0 | W24: 2500 | X24: 0 | Y24: 3950 | Z24: 0 | AA24: 0 | AB24: 0 | AC24: 0 | AD24: 0 | AE24: 0 | AF24: 0 | AG24: 0 | AH24: =+SUM(S24:AG24)-H24 -> 0 | AK24: =+SUM(AK2:AK23) -> 2026625.2 | AL24: =+SUM(AL2:AL23) -> 1757606.5 | AM24: =+SUM(AM2:AM23) -> 3784231.7 | AN24: =+SUM(AN2:AN23) -> 1
B25: 2-002341 | C25: CGL24122385 | D25: 45671 | E25: C0002 | F25: NAPS-GUANAJUATO CAM | G25: 336 | H25: 8114.5 | I25: 1298.32 | J25: =SUM(G25:I25) -> 9748.82 | K25: 9748.82 | L25: =+J25-K25 -> 0 | M25: MXN | Q25: 336 | S25: 4164.5 | T25: 0 | U25: 0 | V25: 0 | W25: 0 | X25: 0 | Y25: 3950 | Z25: 0 | AA25: 0 | AB25: 0 | AC25: 0 | AD25: 0 | AE25: 0 | AF25: 0 | AG25: 0 | AH25: =+SUM(S25:AG25)-H25 -> 0
B26: 2-002342 | C26: CGL24122384 | D26: 45672 | E26: C0002 | F26: NAPS-GUANAJUATO CAM | G26: 336 | H26: 8054.06 | I26: 1288.65 | J26: =SUM(G26:I26) -> 9678.71 | K26: 9678.71 | L26: =+J26-K26 -> 0 | M26: MXN | Q26: 336 | S26: 4104.06 | T26: 0 | U26: 0 | V26: 0 | W26: 0 | X26: 0 | Y26: 3950 | Z26: 0 | AA26: 0 | AB26: 0 | AC26: 0 | AD26: 0 | AE26: 0 | AF26: 0 | AG26: 0 | AH26: =+SUM(S26:AG26)-H26 -> 0
B27: 2-002343 | C27: CGL25012444 | D27: 45672 | E27: C0002 | F27: NAPS-GUANAJUATO CAM | G27: 336 | H27: 8026.46 | I27: 1284.23 | J27: =SUM(G27:I27) -> 9646.69 | K27: 9646.69 | L27: =+J27-K27 -> 0 | M27: MXN | Q27: 336 | S27: 4076.46 | T27: 0 | U27: 0 | V27: 0 | W27: 0 | X27: 0 | Y27: 3950 | Z27: 0 | AA27: 0 | AB27: 0 | AC27: 0 | AD27: 0 | AE27: 0 | AF27: 0 | AG27: 0 | AH27: =+SUM(S27:AG27)-H27 -> 0
B28: 1-002344 | C28: CGL24122434 | D28: 45674 | E28: C0069 | F28: JOINT PRODUCTION HONOR | G28: 781 | H28: 38843.08 | I28: 6214.89 | J28: =SUM(G28:I28) -> 45838.97 | K28: 50246.84 | L28: =+J28-K28 -> -4407.87 | M28: MXN | Q28: 781 | S28: 7259.65 | T28: 2691 | U28: 0 | V28: 0 | W28: 28892.43 | X28: 0 | Y28: 0 | Z28: 0 | AA28: 0 | AB28: 0 | AC28: 0 | AD28: 0 | AE28: 0 | AF28: 0 | AG28: 0 | AH28: =+SUM(S28:AG28)-H28 -> 0
B29: 1-002345 | C29: CGL24122393 | D29: 45677 | E29: C0004 | F29: NAPS-GUANAJUATO AMERICAN BOA | G29: 781 | H29: 87814.69 | I29: 14050.35 | J29: =SUM(G29:I29) -> 102646.04 | K29: 102720.56 | L29: =+J29-K29 -> -74.52 | M29: MXN | Q29: 781 | S29: 6114.69 | T29: 0 | U29: 0 | V29: 0 | W29: 25000 | X29: 0 | Y29: 56700 | Z29: 0 | AA29: 0 | AB29: 0 | AC29: 0 | AD29: 0 | AE29: 0 | AF29: 0 | AG29: 0 | AH29: =+SUM(S29:AG29)-H29 -> 0
B30: 2-002346 | C30: CGL25012457 | D30: 45677 | E30: C0084 | F30: JOINT PRODUCTION TECTRAN | G30: 0 | H30: 43000 | I30: 6880 | J30: =SUM(G30:I30) -> 49880 | K30: 49880 | L30: =+J30-K30 -> 0 | M30: MXN | Q30: 0 | S30: 0 | T30: 0 | U30: 0 | V30: 0 | W30: 0 | X30: 0 | Y30: 43000 | Z30: 0 | AA30: 0 | AB30: 0 | AC30: 0 | AD30: 0 | AE30: 0 | AF30: 0 | AG30: 0 | AH30: =+SUM(S30:AG30)-H30 -> 0
B31: 2-002347 | C31: CGL24122428 | D31: 45677 | E31: C0024 | F31: SELLOS Y RETENES DE SAN LUIS | G31: 23360 | H31: 4076.46 | I31: 652.23 | J31: =SUM(G31:I31) -> 28088.69 | K31: 27212.69 | L31: =+J31-K31 -> 876 | M31: MXN | Q31: 23360 | S31: 4076.46 | T31: 0 | U31: 0 | V31: 0 | W31: 0 | X31: 0 | Y31: 0 | Z31: 0 | AA31: 0 | AB31: 0 | AC31: 0 | AD31: 0 | AE31: 0 | AF31: 0 | AG31: 0 | AH31: =+SUM(S31:AG31)-H31 -> 0
B32: 2-002348 | C32: CGL24122429 | D32: 45677 | E32: C0002 | F32: NAPS-GUANAJUATO CAM | G32: 336 | H32: 4738.54 | I32: 758.17 | J32: =SUM(G32:I32) -> 5832.71 | K32: 5832.71 | L32: =+J32-K32 -> 0 | M32: MXN | Q32: 336 | S32: 4138.54 | T32: 0 | U32: 0 | V32: 0 | W32: 0 | X32: 0 | Y32: 0 | Z32: 0 | AA32: 600 | AB32: 0 | AC32: 0 | AD32: 0 | AE32: 0 | AF32: 0 | AG32: 0 | AH32: =+SUM(S32:AG32)-H32 -> 0
B33: 1-002349 | C33: CGL24122404 | D33: 45678 | E33: C0004 | F33: NAPS-GUANAJUATO AMERICAN BOA | G33: 781 | H33: 73564.69 | I33: 11770.35 | J33: =SUM(G33:I33) -> 86116.04 | K33: 86206.6 | L33: =+J33-K33 -> -90.56 | M33: MXN | Q33: 781 | S33: 6114.69 | T33: 0 | U33: 0 | V33: 0 | W33: 20000 | X33: 0 | Y33: 47450 | Z33: 0 | AA33: 0 | AB33: 0 | AC33: 0 | AD33: 0 | AE33: 0 | AF33: 0 | AG33: 0 | AH33: =+SUM(S33:AG33)-H33 -> 0
B34: 2-002350 | C34: CGL25012465 | D34: 45679 | E34: C0084 | F34: JOINT PRODUCTION TECTRAN | G34: 0 | H34: 7450 | I34: 1192 | J34: =SUM(G34:I34) -> 8642 | K34: 8642 | L34: =+J34-K34 -> 0 | M34: MXN | Q34: 0 | S34: 0 | T34: 0 | U34: 0 | V34: 0 | W34: 0 | X34: 0 | Y34: 7450 | Z34: 0 | AA34: 0 | AB34: 0 | AC34: 0 | AD34: 0 | AE34: 0 | AF34: 0 | AG34: 0 | AH34: =+SUM(S34:AG34)-H34 -> 0
B35: 1-002351 | C35: CGL25012440 | D35: 45679 | E35: C0001 | F35: ARMOR MEXICO IMAGING SUPPLIES | G35: 0 | H35: 101167.89 | I35: 16186.87 | J35: =SUM(G35:I35) -> 117354.76 | K35: 0 | L35: =+J35-K35 -> 117354.76 | M35: MXN | Q35: 0 | S35: 6095.85 | T35: 0 | U35: 0 | V35: 0 | W35: 29072.04 | X35: 0 | Y35: 66000 | Z35: 0 | AA35: 0 | AB35: 0 | AC35: 0 | AD35: 0 | AE35: 0 | AF35: 0 | AG35: 0 | AH35: =+SUM(S35:AG35)-H35 -> 0
B36: 2-002352 | C36: CGL25012474 | D36: 45679 | E36: C0084 | F36: JOINT PRODUCTION TECTRAN | G36: 0 | H36: 20000 | I36: 3200 | J36: =SUM(G36:I36) -> 23200 | K36: 23200 | L36: =+J36-K36 -> 0 | M36: MXN | Q36: 0 | S36: 0 | T36: 0 | U36: 0 | V36: 0 | W36: 0 | X36: 0 | Y36: 20000 | Z36: 0 | AA36: 0 | AB36: 0 | AC36: 0 | AD36: 0 | AE36: 0 | AF36: 0 | AG36: 0 | AH36: =+SUM(S36:AG36)-H36 -> 0
... B54: 1-002374 | C54: CGL25012439 | D54: 45685 | E54: C0004 | F54: NAPS-GUANAJUATO AMERICAN BOA | G54: 781 | H54: 86910 | I54: 13905.6 | J54: =SUM(G54:I54) -> 101596.6 | K54: 101596.6 | L54: =+J54-K54 -> 0 | M54: MXN | Q54: 781 | S54: 6210 | T54: 0 | U54: 0 | V54: 0 | W54: 24000 | X54: 0 | Y54: 56700 | Z54: 0 | AA54: 0 | AB54: 0 | AC54: 0 | AD54: 0 | AE54: 0 | AF54: 0 | AG54: 0 | AH54: =+SUM(S54:AG54)-H54 -> 0
B55: 1-002375 | C55: CGL25012485 | D55: 45685 | E55: C0004 | F55: NAPS-GUANAJUATO AMERICAN BOA | G55: 3599.6 | H55: 1627.5 | I55: 0 | J55: =SUM(G55:I55) -> 5227.1 | K55: 5227.1 | L55: =+J55-K55 -> 0 | M55: MXN | P55: 3599.6 | Q55: 0 | S55: 0 | T55: 0 | U55: 0 | V55: 0 | W55: 0 | X55: 0 | Y55: 0 | Z55: 0 | AA55: 0 | AB55: 0 | AC55: 0 | AD55: 0 | AE55: 1627.5 | AF55: 0 | AG55: 0 | AH55: =+SUM(S55:AG55)-H55 -> 0
B56: 2-002376 | C56: CGL24122407 | D56: 45685 | E56: C0002 | F56: NAPS-GUANAJUATO CAM | G56: 47221 | H56: 15815.59 | I56: 2530.5 | J56: =SUM(G56:I56) -> 65567.09 | K56: 65787.08 | L56: =+J56-K56 -> -219.99 | M56: MXN | Q56: 47221 | S56: 4127.16 | T56: 0 | U56: 0 | V56: 0 | W56: 0 | X56: 0 | Y56: 3950 | Z56: 7738.43 | AA56: 0 | AB56: 0 | AC56: 0 | AD56: 0 | AE56: 0 | AF56: 0 | AG56: 0 | AH56: =+SUM(S56:AG56)-H56 -> 0
B57: 1-002377 | C57: CGL25012473 | D57: 45687 | E57: C0069 | F57: JOINT PRODUCTION HONOR | G57: 781 | H57: 14016.38 | I57: 2242.62 | J57: =SUM(G57:I57) -> 17040 | K57: 21121.67 | L57: =+J57-K57 -> -4081.67 | M57: MXN | Q57: 781 | S57: 7370.71 | T57: 0 | U57: 608.92 | V57: 0 | W57: 2121.75 | X57: 0 | Y57: 3915 | Z57: 0 | AA57: 0 | AB57: 0 | AC57: 0 | AD57: 0 | AE57: 0 | AF57: 0 | AG57: 0 | AH57: =+SUM(S57:AG57)-H57 -> 0
...

Sheet ENE USD 
G1: INFORMACION EN USD | N1: INFORMACION EN MXN
A2: SERIE | B2: FACTURA | C2: TRAFICO | D2: FECHA | E2: CLIENTE | F2: CLIENTENOMBRE | G2: COMPROBADOS | H2: COMPLEMENTARIOS | I2: IVA | J2: SUBTOTAL | K2: ANTICIPO | L2: TOTAL | M2: TIPOCAMBIO | N2: COMPLEMENTARIOS | O2: IVA | P2: SUBTOTAL | Q2: ANTICIPO | R2: TOTAL | U2: SERVICIO LOGISTICO | V2: MANIOBRAS | W2: LIBERACION DE DOCUMENTOS | X2: HONORARIOS | Y2: GASTOS EN DESTINO | Z2: CUOTA | AB2: SERVICIO LOGISTICO | AC2: MANIOBRAS | AD2: LIBERACION DE DOCUMENTOS | AE2: HONORARIOS | AF2: GASTOS EN DESTINO | AG2: CUOTA
B3: 1-002334 | C3: CGL24122417 | D3: 45670 | E3: C0067 | F3: ND AUTOMOTIVE SYSTEMS MEXICO | G3: 0 | H3: =994+525.49 -> 1519.49 | I3: 0 | J3: =SUM(G3:I3) -> 1519.49 | K3: 0 | L3: =J3-K3 -> 1519.49 | M3: 20.7045 | N3: =H3*M3 -> 31460.281 | O3: =I3*M3 -> 0 | P3: =J3*M3 -> 31460.281 | Q3: =M3*K3 -> 0 | R3: =L3*M3 -> 31460.281 | U3: 994 | Y3: 525.49 | AB3: =U3*M3 -> 20580.273 | AC3: =+V3*M3 -> 0 | AD3: =+M3*W3 -> 0 | AE3: =+X3*M3 -> 0 | AF3: =+Y3*M3 -> 10880.008 | AG3: =+Z3*M3 -> 0
B4: 2-002356 | C4: CGL24112355 | D4: 45680 | E4: C0084 | F4: JOINT PRODUCTION TECTRAN | G4: 0 | H4: 875 | I4: 0 | J4: =SUM(G4:I4) -> 875 | K4: 0 | L4: =J4-K4 -> 875 | M4: 20.7045 | N4: =H4*M4 -> 18116.438 | O4: =I4*M4 -> 0 | P4: =J4*M4 -> 18116.438 | Q4: =M4*K4 -> 0 | R4: =L4*M4 -> 18116.438 | U4: 875 | AB4: =U4*M4 -> 18116.438 | AC4: =+V4*M4 -> 0 | AD4: =+M4*W4 -> 0 | AE4: =+X4*M4 -> 0 | AF4: =+Y4*M4 -> 0 | AG4: =+Z4*M4 -> 0
B5: 2-002357 | C5: CGL24122435 | D5: 45680 | E5: C0084 | F5: JOINT PRODUCTION TECTRAN | G5: 0 | H5: 6850 | I5: 0 | J5: =SUM(G5:I5) -> 6850 | K5: 0 | L5: =J5-K5 -> 6850 | M5: 20.482 | N5: =H5*M5 -> 140301.7 | O5: =I5*M5 -> 0 | P5: =J5*M5 -> 140301.7 | Q5: =M5*K5 -> 0 | R5: =L5*M5 -> 140301.7 | U5: 6850 | AB5: =U5*M5 -> 140301.7 | AC5: =+V5*M5 -> 0 | AD5: =+M5*W5 -> 0 | AE5: =+X5*M5 -> 0 | AF5: =+Y5*M5 -> 0 | AG5: =+Z5*M5 -> 0
B6: 1-002358 | C6: CGL24122430 | D6: 45681 | E6: C0089 | F6: CHEMICAL COLOR DE MEXICO | G6: 0 | H6: =3750+360 -> 4110 | I6: 0 | J6: =SUM(G6:I6) -> 4110 | K6: 4110 | L6: =J6-K6 -> 0 | M6: 20.3943 | N6: =H6*M6 -> 83820.573 | O6: =I6*M6 -> 0 | P6: =J6*M6 -> 83820.573 | Q6: =M6*K6 -> 83820.573 | R6: =L6*M6 -> 0 | U6: 3750 | Y6: 360 | AB6: =U6*M6 -> 76478.625 | AC6: =+V6*M6 -> 0 | AD6: =+M6*W6 -> 0 | AE6: =+X6*M6 -> 0 | AF6: =+Y6*M6 -> 7341.948 | AG6: =+Z6*M6 -> 0
B7: 1-002360 | C7: CGL24122432 | D7: 45681 | E7: C0001 | F7: ARMOR MEXICO IMAGING SUPPLIES | G7: 0 | H7: =4100+1500 -> 5600 | I7: 0 | J7: =SUM(G7:I7) -> 5600 | K7: 0 | L7: =J7-K7 -> 5600 | M7: 20.3943 | N7: =H7*M7 -> 114208.08 | O7: =I7*M7 -> 0 | P7: =J7*M7 -> 114208.08 | Q7: =M7*K7 -> 0 | R7: =L7*M7 -> 114208.08 | U7: 4100 | Y7: 1500 | AB7: =U7*M7 -> 83616.63 | AC7: =+V7*M7 -> 0 | AD7: =+M7*W7 -> 0 | AE7: =+X7*M7 -> 0 | AF7: =+Y7*M7 -> 30591.45 | AG7: =+Z7*M7 -> 0
B8: 2-002380 | C8: CGL25012470 | D8: 45687 | E8: C0084 | F8: JOINT PRODUCTION TECTRAN | G8: 0 | H8: 6125 | I8: 0 | J8: =SUM(G8:I8) -> 6125 | K8: 0 | L8: =J8-K8 -> 6125 | M8: 20.5677 | N8: =H8*M8 -> 125977.16 | O8: =I8*M8 -> 0 | P8: =J8*M8 -> 125977.16 | Q8: =M8*K8 -> 0 | R8: =L8*M8 -> 125977.16 | U8: 6125 | AB8: =U8*M8 -> 125977.16 | AC8: =+V8*M8 -> 0 | AD8: =+M8*W8 -> 0 | AE8: =+X8*M8 -> 0 | AF8: =+Y8*M8 -> 0 | AG8: =+Z8*M8 -> 0
B9: 1-002381 | C9: CGL24122397 | D9: 45687 | E9: C0067 | F9: ND AUTOMOTIVE SYSTEMS MEXICO | G9: 0 | H9: 375 | I9: =+H9*0.16 -> 60 | J9: =SUM(G9:I9) -> 435 | K9: 0 | L9: =J9-K9 -> 435 | M9: 20.5677 | N9: =H9*M9 -> 7712.8875 | O9: =I9*M9 -> 1234.062 | P9: =J9*M9 -> 8946.9495 | Q9: =M9*K9 -> 0 | R9: =L9*M9 -> 8946.9495 | Y9: 375 | AB9: =U9*M9 -> 0 | AC9: =+V9*M9 -> 0 | AD9: =+M9*W9 -> 0 | AE9: =+X9*M9 -> 0 | AF9: =+Y9*M9 -> 7712.8875 | AG9: =+Z9*M9 -> 0
B10: 1-002382 | C10: CGL24071864 | D10: 45687 | E10: C0067 | F10: ND AUTOMOTIVE SYSTEMS MEXICO | G10: =36232.6+539.4 -> 36772 | H10: =75+175 -> 250 | I10: 0 | J10: =SUM(G10:I10) -> 37022 | K10: 36482.6 | L10: =J10-K10 -> 539.4 | M10: 20.5677 | N10: =H10*M10 -> 5141.925 | O10: =I10*M10 -> 0 | P10: =J10*M10 -> 761457.39 | Q10: =M10*K10 -> 750363.17 | R10: =L10*M10 -> 11094.217 | W10: 175 | Z10: 75 | AB10: =U10*M10 -> 0 | AC10: =+V10*M10 -> 0 | AD10: =+M10*W10 -> 3599.3475 | AE10: =+X10*M10 -> 0 | AF10: =+Y10*M10 -> 0 | AG10: =+Z10*M10 -> 1542.5775
B11: 1-002387 | C11: CGL25012469 | D11: 45688 | E11: C0090 | F11: INVICONT OÜ | G11: 0 | H11: 60190 | I11: 0 | J11: =SUM(G11:I11) -> 60190 | K11: 60190 | L11: =J11-K11 -> 0 | M11: 20.4497 | N11: =H11*M11 -> 1230867.4 | O11: =I11*M11 -> 0 | P11: =J11*M11 -> 1230867.4 | Q11: =M11*K11 -> 1230867.4 | R11: =L11*M11 -> 0 | V11: 34980 | W11: 350 | X11: 24860 | AB11: =U11*M11 -> 0 | AC11: =+V11*M11 -> 715330.51 | AD11: =+M11*W11 -> 7157.395 | AE11: =+X11*M11 -> 508379.54 | AF11: =+Y11*M11 -> 0 | AG11: =+Z11*M11 -> 0
J12: =SUM(G12:I12) -> 0 | L12: =J12-K12 -> 0 | N12: =H12*M12 -> 0 | O12: =I12*M12 -> 0 | P12: =J12*M12 -> 0 | Q12: =M12*K12 -> 0 | R12: =L12*M12 -> 0 | AB12: =U12*M12 -> 0 | AC12: =+V12*M12 -> 0 | AD12: =+M12*W12 -> 0 | AE12: =+X12*M12 -> 0 | AF12: =+Y12*M12 -> 0 | AG12: =+Z12*M12 -> 0
J13: =SUM(G13:I13) -> 0 | L13: =J13-K13 -> 0 | N13: =H13*M13 -> 0 | O13: =I13*M13 -> 0 | P13: =J13*M13 -> 0 | Q13: =M13*K13 -> 0 | R13: =L13*M13 -> 0 | AB13: =U13*M13 -> 0 | AC13: =+V13*M13 -> 0 | AD13: =+M13*W13 -> 0 | AE13: =+X13*M13 -> 0 | AF13: =+Y13*M13 -> 0 | AG13: =+Z13*M13 -> 0
J14: =SUM(G14:I14) -> 0 | L14: =J14-K14 -> 0 | N14: =H14*M14 -> 0 | O14: =I14*M14 -> 0 | P14: =J14*M14 -> 0 | Q14: =M14*K14 -> 0 | R14: =L14*M14 -> 0 | AB14: =U14*M14 -> 0 | AC14: =+V14*M14 -> 0 | AD14: =+M14*W14 -> 0 | AE14: =+X14*M14 -> 0 | AF14: =+Y14*M14 -> 0 | AG14: =+Z14*M14 -> 0
J15: =SUM(G15:I15) -> 0 | L15: =J15-K15 -> 0 | N15: =H15*M15 -> 0 | O15: =I15*M15 -> 0 | P15: =J15*M15 -> 0 | Q15: =M15*K15 -> 0 | R15: =L15*M15 -> 0 | AB15: =U15*M15 -> 0 | AC15: =+V15*M15 -> 0 | AD15: =+M15*W15 -> 0 | AE15: =+X15*M15 -> 0 | AF15: =+Y15*M15 -> 0 | AG15: =+Z15*M15 -> 0
J16: =SUM(G16:I16) -> 0 | L16: =J16-K16 -> 0 | N16: =H16*M16 -> 0 | O16: =I16*M16 -> 0 | P16: =J16*M16 -> 0 | Q16: =M16*K16 -> 0 | R16: =L16*M16 -> 0 | AB16: =U16*M16 -> 0 | AC16: =+V16*M16 -> 0 | AD16: =+M16*W16 -> 0 | AE16: =+X16*M16 -> 0 | AF16: =+Y16*M16 -> 0 | AG16: =+Z16*M16 -> 0
J17: =SUM(G17:I17) -> 0 | L17: =J17-K17 -> 0 | N17: =H17*M17 -> 0 | O17: =I17*M17 -> 0 | P17: =J17*M17 -> 0 | Q17: =M17*K17 -> 0 | R17: =L17*M17 -> 0 | AB17: =U17*M17 -> 0 | AC17: =+V17*M17 -> 0 | AD17: =+M17*W17 -> 0 | AE17: =+X17*M17 -> 0 | AF17: =+Y17*M17 -> 0 | AG17: =+Z17*M17 -> 0
J18: =SUM(G18:I18) -> 0 | L18: =J18-K18 -> 0 | N18: =H18*M18 -> 0 | O18: =I18*M18 -> 0 | P18: =J18*M18 -> 0 | Q18: =M18*K18 -> 0 | R18: =L18*M18 -> 0 | AB18: =U18*M18 -> 0 | AC18: =+V18*M18 -> 0 | AD18: =+M18*W18 -> 0 | AE18: =+X18*M18 -> 0 | AF18: =+Y18*M18 -> 0 | AG18: =+Z18*M18 -> 0
G19: =+SUM(G3:G18) -> 36772 | H19: =+SUM(H3:H18) -> 85894.49 | I19: =+SUM(I3:I18) -> 60 | J19: =+SUM(J3:J18) -> 122726.49 | K19: =+SUM(K3:K18) -> 100782.6 | L19: =+SUM(L3:L18) -> 21943.89 | N19: =+SUM(N3:N18) -> 1757606.5 | O19: =+SUM(O3:O18) -> 1234.062 | P19: =+SUM(P3:P18) -> 2515156 | Q19: =+SUM(Q3:Q18) -> 2065051.2 | R19: =+SUM(R3:R18) -> 450104.83 | U19: =+SUM(U3:U18) -> 22694 | V19: =+SUM(V3:V18) -> 34980 | W19: =+SUM(W3:W18) -> 525 | X19: =+SUM(X3:X18) -> 24860 | Y19: =+SUM(Y3:Y18) -> 2760.49 | Z19: =+SUM(Z3:Z18) -> 75 | AB19: =+SUM(AB3:AB18) -> 465070.83 | AC19: =+SUM(AC3:AC18) -> 715330.51 | AD19: =+SUM(AD3:AD18) -> 10756.743 | AE19: =+SUM(AE3:AE18) -> 508379.54 | AF19: =+SUM(AF3:AF18) -> 56526.293 | AG19: =+SUM(AG3:AG18) -> 1542.5775
Z20: =+SUM(T19:Z19) -> 85894.49 | AG20: =+SUM(AB19:AG19) -> 1757606.5
Z21: =+Z20-H19 -> 0 | AG21: =+AG20-N19 -> 0

Sheet FEB MXN
A1: SERIE | B1: FACTURA | C1: TRAFICO | D1: FECHA | E1: CLIENTE | F1: CLIENTE NOMBRE | G1: COMPROBADOS | H1: COMPLEMENTARIOS | I1: IVA | J1: SUBTOTAL | K1: ANTICIPO | L1: TOTAL | M1: MONEDA | P1: DOCUMENTACION, ALMACENAJES Y MANIOBRAS ( TER) | Q1: IMPUESTOS ADUANALES (TER) | S1: HONORARIOS | T1: REVALIDACION GUIA / BOL | U1: MANIOBRAS | V1: ALMACENAJES | W1: SERVICIOS LOGISTICOS | X1: CONSOLIDACION DE ENTRADAS | Y1: SERVICIO EXTRAORDINARIO | Z1: ACONDICIONAMIENTO DE EMBALAJE | AA1: LIBERACION DE DOCUMENTOS | AE1: MXN | AF1: USD | AG1: TOTAL | AH1: PORCENTAJE
B2: 1-002395 | C2: CGL24122432 | D2: 45694 | E2: C0001 | F2: ARMOR MEXICO IMAGING SUPPLIES | G2: 0 | H2: 107360.24 | I2: 17177.64 | J2: =SUM(G2:I2) -> 124537.88 | K2: 0 | L2: =+J2-K2 -> 124537.88 | M2: MXN | P2: 0 | Q2: 0 | S2: 6162.9 | T2: 0 | U2: 29072.04 | V2: 2790.3 | W2: 69335 | X2: 0 | Y2: 0 | Z2: 0 | AA2: 0 | AB2: =+SUM(S2:AA2)-H2 -> 0 | AD2: HONORARIOS | AE2: =+S77 -> 421824.29 | AG2: =SUM(AE2:AF2) -> 421824.29 | AH2: =+AG2/AG24 -> 0.1948623
B3: 1-002396 | C3: CGL25012475 | D3: 45694 | E3: C0001 | F3: ARMOR MEXICO IMAGING SUPPLIES | G3: 0 | H3: 73868.29 | I3: 11818.93 | J3: =SUM(G3:I3) -> 85687.22 | K3: 0 | L3: =+J3-K3 -> 85687.22 | M3: MXN | P3: 0 | Q3: 0 | S3: 6118.29 | T3: 0 | U3: 25750 | V3: 0 | W3: 42000 | X3: 0 | Y3: 0 | Z3: 0 | AA3: 0 | AB3: =+SUM(S3:AA3)-H3 -> 0 | AD3: REVALIDACION GUIA / BOL | AE3: =+T77 -> 13310.6 | AF3: =+'FEB USD '!AC19 -> 10188.894 | AG3: =SUM(AE3:AF3) -> 23499.494 | AH3: =+AG3/AG24 -> 0.010855623
B4: 1-002397 | C4: CGL25012515 | D4: 45694 | E4: C0069 | F4: JOINT PRODUCTION HONOR | G4: 781 | H4: 13293.3 | I4: 2126.93 | J4: =SUM(G4:I4) -> 16201.23 | K4: 25378.07 | L4: =+J4-K4 -> -9176.84 | M4: MXN | P4: 0 | Q4: 781 | S4: 7404.37 | T4: 0 | U4: 5888.93 | V4: 0 | X4: 0 | Y4: 0 | Z4: 0 | AA4: 0 | AB4: =+SUM(S4:AA4)-H4 -> 0 | AD4: MANIOBRAS | AE4: =+U77 -> 420886.31 | AG4: =SUM(AE4:AF4) -> 420886.31 | AH4: =+AG4/AG24 -> 0.19442899
B5: 1-002399 | C5: CGL25012513 | D5: 45694 | E5: C0004 | F5: NAPS-GUANAJUATO AMERICAN BOA | G5: =781+295 -> 1076 | H5: 143742.45 | I5: 22998.79 | J5: =SUM(G5:I5) -> 167817.24 | K5: 167817.25 | L5: =+J5-K5 -> -0.01 | M5: MXN | P5: 295 | Q5: 781 | S5: 30125.61 | T5: 0 | U5: 65911.84 | V5: 0 | W5: 47705 | X5: 0 | Y5: 0 | Z5: 0 | AA5: 0 | AB5: =+SUM(S5:AA5)-H5 -> 0 | AD5: ALMACENAJES | AE5: =+V77 -> 3967.78 | AG5: =SUM(AE5:AF5) -> 3967.78 | AH5: =+AG5/AG24 -> 0.0018329213
B6: 2-002401 | C6: CGL25012522 | D6: 45695 | E6: C0001 | F6: ARMOR MEXICO IMAGING SUPPLIES | G6: 0 | H6: 26000.04 | I6: 4160.01 | J6: =SUM(G6:I6) -> 30160.05 | K6: 0 | L6: =+J6-K6 -> 30160.05 | M6: MXN | P6: 0 | Q6: 0 | S6: 4140.04 | T6: 0 | U6: 0 | V6: 0 | W6: 21860 | X6: 0 | Y6: 0 | Z6: 0 | AA6: 0 | AB6: =+SUM(S6:AA6)-H6 -> 0 | AD6: SERVICIOS LOGISTICOS | AE6: =+W77 -> 999662.55 | AF6: =+'FEB USD '!AB19 -> 160463.12 | AG6: =SUM(AE6:AF6) -> 1160125.7 | AH6: =+AG6/AG24 -> 0.53592161
B7: 2-002402 | C7: CGL25012464 | D7: 45695 | E7: C0069 | F7: JOINT PRODUCTION HONOR | G7: =336+336 -> 672 | H7: 15295.72 | I7: 2447.32 | J7: =SUM(G7:I7) -> 18415.04 | K7: 18415.04 | L7: =+J7-K7 -> 0 | M7: MXN | P7: 0 | Q7: =336+336 -> 672 | S7: =7647.86+7647.86 -> 15295.72 | T7: 0 | U7: 0 | V7: 0 | W7: 0 | X7: 0 | Y7: 0 | Z7: 0 | AA7: 0 | AB7: =+SUM(S7:AA7)-H7 -> 0 | AD7: CONSOLIDACION DE ENTRADAS | AE7: =+X77 -> 38326.46 | AG7: =SUM(AE7:AF7) -> 38326.46 | AH7: =+AG7/AG24 -> 0.01770496
B8: 1-002403 | C8: CGL25012501 | D8: 45699 | E8: C0084 | F8: JOINT PRODUCTION TECTRAN | G8: 0 | H8: 21320.23 | I8: 3411.24 | J8: =SUM(G8:I8) -> 24731.47 | K8: 24731.47 | L8: =+J8-K8 -> 0 | M8: MXN | P8: 0 | Q8: 0 | S8: 0 | T8: 0 | U8: 0 | V8: 0 | W8: 21320.23 | X8: 0 | Y8: 0 | Z8: 0 | AA8: 0 | AB8: =+SUM(S8:AA8)-H8 -> 0 | AD8: SERVICIO EXTRAORDINARIO | AE8: =+Y77 -> 71000 | AG8: =SUM(AE8:AF8) -> 71000 | AH8: =+AG8/AG24 -> 0.032798545
B9: 2-002404 | C9: CGL25022547 | D9: 45699 | E9: C0081 | F9: JOINT PRODUCTION BLACK SMITH | G9: 0 | H9: 66000 | I9: 10560 | J9: =SUM(G9:I9) -> 76560 | K9: 76560 | L9: =+J9-K9 -> 0 | M9: MXN | P9: 0 | Q9: 0 | S9: 0 | T9: 0 | U9: 0 | V9: 0 | W9: 66000 | X9: 0 | Y9: 0 | Z9: 0 | AA9: 0 | AB9: =+SUM(S9:AA9)-H9 -> 0 | AD9: ACONDICIONAMIENTO DE EMBALAJE | AE9: =+Z77 -> 2550 | AG9: =SUM(AE9:AF9) -> 2550 | AH9: =+AG9/AG24 -> 0.0011779759
B10: 2-002405 | C10: CGL25012488 | D10: 45699 | E10: C0002 | F10: NAPS-GUANAJUATO CAM | G10: 1695 | H10: 8039.94 | I10: 1286.39 | J10: =SUM(G10:I10) -> 11021.33 | K10: 11021.33 | L10: =+J10-K10 -> 0 | M10: MXN | P10: 0 | Q10: 1695 | S10: 4089.94 | T10: 0 | U10: 0 | V10: 0 | W10: 3950 | X10: 0 | Y10: 0 | Z10: 0 | AA10: 0 | AB10: =+SUM(S10:AA10)-H10 -> 0 | AD10: LIBERACION DE DOCUMENTOS | AE10: =+AA77 -> 1597.5 | AF10: =+'FEB USD '!AD19 -> 4815.5495 | AG10: =SUM(AE10:AF10) -> 6413.0495 | AH10: =+AG10/AG24 -> 0.0029625168
B11: 2-002406 | C11: CGL25012528 | D11: 45699 | E11: C0002 | F11: NAPS-GUANAJUATO CAM | G11: 336 | H11: 4121.36 | I11: 659.42 | J11: =SUM(G11:I11) -> 5116.78 | K11: 5116.78 | L11: =+J11-K11 -> 0 | M11: MXN | P11: 0 | Q11: 336 | S11: 4121.36 | T11: 0 | U11: 0 | V11: 0 | W11: 0 | X11: 0 | Y11: 0 | Z11: 0 | AA11: 0 | AB11: =+SUM(S11:AA11)-H11 -> 0 | AD11: GASTOS EN DESTINO | AF11: =+'FEB USD '!AF19 -> 14600.236 | AG11: =SUM(AE11:AF11) -> 14600.236 | AH11: =+AG11/AG24 -> 0.0067445984
B12: 2-002407 | C12: CGL24122416 | D12: 45699 | E12: C0002 | F12: NAPS-GUANAJUATO CAM | G12: 19120 | H12: 8071.36 | I12: 1291.42 | J12: =SUM(G12:I12) -> 28482.78 | K12: 28482.78 | L12: =+J12-K12 -> 0 | M12: MXN | P12: 0 | Q12: 19120 | S12: 4121.36 | T12: 0 | U12: 0 | V12: 0 | W12: 3950 | X12: 0 | Y12: 0 | Z12: 0 | AA12: 0 | AB12: =+SUM(S12:AA12)-H12 -> 0 | AD12: CUOTA | AF12: =+'FEB USD '!AG19 -> 1536.8775 | AG12: =SUM(AE12:AF12) -> 1536.8775 | AH12: =+AG12/AG24 -> 0.00070996262
B13: 2-002408 | C13: CGL25022551 | D13: 45699 | E13: C0002 | F13: NAPS-GUANAJUATO CAM | G13: 781 | H13: 8035.36 | I13: 1285.66 | J13: =SUM(G13:I13) -> 10102.02 | K13: 10102.02 | L13: =+J13-K13 -> 0 | M13: MXN | P13: 0 | Q13: 781 | S13: 4085.36 | T13: 0 | U13: 0 | V13: 0 | W13: 3950 | X13: 0 | Y13: 0 | Z13: 0 | AA13: 0 | AB13: =+SUM(S13:AA13)-H13 -> 0 | AG13: =SUM(AE13:AF13) -> 0 | AH13: =+AG13/AG24 -> 0
B14: 2-002409 | C14: CGL25012511 | D14: 45699 | E14: C0002 | F14: NAPS-GUANAJUATO CAM | G14: 781 | H14: 8035.36 | I14: 1285.66 | J14: =SUM(G14:I14) -> 10102.02 | K14: 10102.02 | L14: =+J14-K14 -> 0 | M14: MXN | P14: 0 | Q14: 781 | S14: 4085.36 | T14: 0 | U14: 0 | V14: 0 | W14: 3950 | X14: 0 | Y14: 0 | Z14: 0 | AA14: 0 | AB14: =+SUM(S14:AA14)-H14 -> 0 | AG14: =SUM(AE14:AF14) -> 0 | AH14: =+AG14/AG24 -> 0
B15: 2-002410 | C15: CGL25012507 | D15: 45699 | E15: C0002 | F15: NAPS-GUANAJUATO CAM | G15: 1782 | H15: 8022.43 | I15: 1283.59 | J15: =SUM(G15:I15) -> 11088.02 | K15: 11088.02 | L15: =+J15-K15 -> 0 | M15: MXN | P15: 0 | Q15: 1782 | S15: 4072.43 | T15: 0 | U15: 0 | V15: 0 | W15: 3950 | X15: 0 | Y15: 0 | Z15: 0 | AA15: 0 | AB15: =+SUM(S15:AA15)-H15 -> 0 | AG15: =SUM(AE15:AF15) -> 0 | AH15: =+AG15/AG24 -> 0
B16: 2-002411 | C16: CGL25012456 | D16: 45699 | E16: C0002 | F16: NAPS-GUANAJUATO CAM | G16: 1515 | H16: 8025.02 | I16: 1284 | J16: =SUM(G16:I16) -> 10824.02 | K16: 10824.02 | L16: =+J16-K16 -> 0 | M16: MXN | P16: 0 | Q16: 1515 | S16: 4075.02 | T16: 0 | U16: 0 | V16: 0 | W16: 3950 | X16: 0 | Y16: 0 | Z16: 0 | AA16: 0 | AB16: =+SUM(S16:AA16)-H16 -> 0 | AG16: =SUM(AE16:AF16) -> 0 | AH16: =+AG16/AG24 -> 0
B17: 2-002412 | C17: CGL25012539 | D17: 45699 | E17: C0001 | F17: ARMOR MEXICO IMAGING SUPPLIES | G17: 0 | H17: 9013.77 | I17: 1442.2 | J17: =SUM(G17:I17) -> 10455.97 | K17: 0 | L17: =+J17-K17 -> 10455.97 | M17: MXN | P17: 0 | Q17: 0 | S17: 4085.2 | T17: 0 | U17: 0 | V17: 0 | W17: 4928.57 | X17: 0 | Y17: 0 | Z17: 0 | AA17: 0 | AB17: =+SUM(S17:AA17)-H17 -> 0 | AG17: =SUM(AE17:AF17) -> 0 | AH17: =+AG17/AG24 -> 0
B18: 2-002413 | C18: CGL25012479 | D18: 45700 | E18: C0002 | F18: NAPS-GUANAJUATO CAM | G18: 2305 | H18: 9677.26 | I18: 1548.36 | J18: =SUM(G18:I18) -> 13530.62 | K18: 11674.62 | L18: =+J18-K18 -> 1856 | M18: MXN | P18: 0 | Q18: 2305 | S18: 4127.26 | T18: 0 | U18: 0 | V18: 0 | W18: 3950 | X18: 0 | Y18: 1600 | Z18: 0 | AA18: 0 | AB18: =+SUM(S18:AA18)-H18 -> 0 | AG18: =SUM(AE18:AF18) -> 0 | AH18: =+AG18/AG24 -> 0
B19: 2-002414 | C19: CGL25012512 | D19: 45700 | E19: C0002 | F19: NAPS-GUANAJUATO CAM | G19: 38418 | H19: 20291.44 | I19: 3246.63 | J19: =SUM(G19:I19) -> 61956.07 | K19: 61956.07 | L19: =+J19-K19 -> 0 | M19: MXN | P19: 0 | Q19: 38418 | S19: 4085.36 | T19: 0 | U19: 0 | V19: 0 | W19: 3950 | X19: 12256.08 | Y19: 0 | Z19: 0 | AA19: 0 | AB19: =+SUM(S19:AA19)-H19 -> 0
B20: 1-002415 | C20: CGL25022546 | D20: 45700 | E20: C0001 | F20: ARMOR MEXICO IMAGING SUPPLIES | G20: 0 | H20: 38816.61 | I20: 6210.66 | J20: =SUM(G20:I20) -> 45027.27 | K20: 0 | L20: =+J20-K20 -> 45027.27 | M20: MXN | P20: 0 | Q20: 0 | S20: 4102.5 | T20: 3737.5 | U20: 19501.61 | V20: 0 | W20: 11475 | X20: 0 | Y20: 0 | Z20: 0 | AA20: 0 | AB20: =+SUM(S20:AA20)-H20 -> 0
B21: 2-002417 | C21: CGL25022550 | D21: 45701 | E21: C0081 | F21: JOINT PRODUCTION BLACK SMITH | G21: 0 | H21: 22000 | I21: 3520 | J21: =SUM(G21:I21) -> 25520 | K21: 25520 | L21: =+J21-K21 -> 0 | M21: MXN | P21: 0 | Q21: 0 | S21: 0 | T21: 0 | U21: 0 | V21: 0 | W21: 22000 | X21: 0 | Y21: 0 | Z21: 0 | AA21: 0 | AB21: =+SUM(S21:AA21)-H21 -> 0
B22: 1-002418 | C22: CGL25012491 | D22: 45701 | E22: C0012 | F22: MEGALUMINIO SERVICIOS | G22: 5295 | H22: 21926.3 | I22: 3508.21 | J22: =SUM(G22:I22) -> 30729.51 | K22: 31002.76 | L22: =+J22-K22 -> -273.25 | M22: MXN | P22: 0 | Q22: 5295 | S22: 6500 | T22: 0 | U22: 10348.6 | V22: 0 | W22: 5077.7 | X22: 0 | Y22: 0 | Z22: 0 | AA22: 0 | AB22: =+SUM(S22:AA22)-H22 -> 0
B23: 1-002419 | C23: CGL25012492 | D23: 45701 | E23: C0012 | F23: MEGALUMINIO SERVICIOS | G23: 30380 | H23: 22092.27 | I23: 3534.77 | J23: =SUM(G23:I23) -> 56007.04 | K23: 56009.76 | L23: =+J23-K23 -> -2.72 | M23: MXN | P23: 0 | Q23: 30380 | S23: 6500 | T23: 652.6 | U23: =9760+4079.67 -> 13839.67 | V23: 0 | W23: 1100 | X23: 0 | Y23: 0 | Z23: 0 | AA23: 0 | AB23: =+SUM(S23:AA23)-H23 -> 0 | AE23: 0 | AG23: =SUM(AE23:AF23) -> 0 | AH23: =+AG23/AG24 -> 0
B24: 1-002420 | C24: CGL25012510 | D24: 45701 | E24: C0069 | F24: JOINT PRODUCTION HONOR | G24: 781 | H24: 61555.79 | I24: 9848.93 | J24: =SUM(G24:I24) -> 72185.72 | K24: 971053.49 | L24: =+J24-K24 -> -898867.77 | M24: MXN | P24: 0 | Q24: 781 | S24: 7341.94 | T24: 0 | U24: 54213.85 | V24: 0 | W24: 0 | X24: 0 | Y24: 0 | Z24: 0 | AA24: 0 | AB24: =+SUM(S24:AA24)-H24 -> 0 | AE24: =+SUM(AE2:AE23) -> 1973125.5 | AF24: =+SUM(AF2:AF23) -> 191604.67 | AG24: =+SUM(AG2:AG23) -> 2164730.2 | AH24: =+SUM(AH2:AH23) -> 1
B25: 1-002423 | C25: CGL25022541 | D25: 45701 | E25: C0069 | F25: JOINT PRODUCTION HONOR | G25: 781 | H25: 10776.17 | I25: 1724.18 | J25: =SUM(G25:I25) -> 13281.35 | K25: 19752.67 | L25: =+J25-K25 -> -6471.32 | M25: MXN | P25: 0 | Q25: 781 | S25: 7361.89 | T25: 0 | U25: 3414.28 | V25: 0 | W25: 0 | X25: 0 | Y25: 0 | Z25: 0 | AA25: 0 | AB25: =+SUM(S25:AA25)-H25 -> 0
B26: 1-002424 | C26: CGL25012463 | D26: 45701 | E26: C0005 | F26: HAHN AUTOMATION | G26: 12384 | H26: 9336.15 | I26: 1493.79 | J26: =SUM(G26:I26) -> 23213.94 | K26: 23213.94 | L26: =+J26-K26 -> 0 | M26: MXN | P26: 0 | Q26: 12384 | S26: 4447.41 | T26: 0 | U26: 2788.74 | V26: 0 | W26: 2100 | X26: 0 | Y26: 0 | Z26: 0 | AA26: 0 | AB26: =+SUM(S26:AA26)-H26 -> 0
B27: 2-002425 | C27: CGL25022548 | D27: 45701 | E27: C0081 | F27: JOINT PRODUCTION BLACK SMITH | G27: 0 | H27: 20000 | I27: 3200 | J27: =SUM(G27:I27) -> 23200 | K27: 23200 | L27: =+J27-K27 -> 0 | M27: MXN | P27: 0 | Q27: 0 | S27: 0 | T27: 0 | U27: 0 | V27: 0 | W27: 20000 | X27: 0 | Y27: 0 | Z27: 0 | AA27: 0 | AB27: =+SUM(S27:AA27)-H27 -> 0
B28: 2-002428 | C28: CGL25012530 | D28: 45705 | E28: C0069 | F28: JOINT PRODUCTION HONOR | G28: 336 | H28: 100458.15 | I28: 16073.3 | J28: =SUM(G28:I28) -> 116867.45 | K28: 116867.45 | L28: =+J28-K28 -> 0 | M28: MXN | P28: 0 | Q28: 336 | S28: 100458.15 | T28: 0 | U28: 0 | V28: 0 | W28: 0 | X28: 0 | Y28: 0 | Z28: 0 | AA28: 0 | AB28: =+SUM(S28:AA28)-H28 -> 0
B29: 1-002429 | C29: CGL25022559 | D29: 45705 | E29: C0001 | F29: ARMOR MEXICO IMAGING SUPPLIES | G29: 0 | H29: 11406.38 | I29: 1825.03 | J29: =SUM(G29:I29) -> 13231.41 | K29: 0 | L29: =+J29-K29 -> 13231.41 | M29: MXN | P29: 0 | Q29: 0 | S29: 4113.36 | T29: 1500 | U29: 2115.54 | V29: 1177.48 | W29: 2500 | X29: 0 | Y29: 0 | Z29: 0 | AA29: 0 | AB29: =+SUM(S29:AA29)-H29 -> 0
B30: 2-002430 | C30: CGL25022560 | D30: 45705 | E30: C0001 | F30: ARMOR MEXICO IMAGING SUPPLIES | G30: 0 | H30: 41110.24 | I30: 6577.64 | J30: =SUM(G30:I30) -> 47687.88 | K30: 0 | L30: =+J30-K30 -> 47687.88 | M30: MXN | P30: 0 | Q30: 0 | S30: 4110.24 | T30: 0 | U30: 0 | V30: 0 | W30: 37000 | X30: 0 | Y30: 0 | Z30: 0 | AA30: 0 | AB30: =+SUM(S30:AA30)-H30 -> 0
B31: 2-002431 | C31: CGL25022555 | D31: 45706 | E31: C0002 | F31: NAPS-GUANAJUATO CAM | G31: 336 | H31: 6985.2 | I31: 1117.63 | J31: =SUM(G31:I31) -> 8438.83 | K31: 8438.83 | L31: =+J31-K31 -> 0 | M31: MXN | P31: 0 | Q31: 336 | S31: 3035.2 | T31: 0 | U31: 0 | V31: 0 | W31: 3950 | X31: 0 | Y31: 0 | Z31: 0 | AA31: 0 | AB31: =+SUM(S31:AA31)-H31 -> 0
B32: 2-002432 | C32: CGL25022565 | D32: 45706 | E32: C0001 | F32: ARMOR MEXICO IMAGING SUPPLIES | G32: 0 | H32: 41113.6 | I32: 6578.18 | J32: =SUM(G32:I32) -> 47691.78 | K32: 0 | L32: =+J32-K32 -> 47691.78 | M32: MXN | P32: 0 | Q32: 0 | S32: 4113.6 | T32: 0 | U32: 0 | V32: 0 | W32: 37000 | X32: 0 | Y32: 0 | Z32: 0 | AA32: 0 | AB32: =+SUM(S32:AA32)-H32 -> 0
B33: 2-002433 | C33: CGL25012533 | D33: 45706 | E33: C0002 | F33: NAPS-GUANAJUATO CAM | G33: 336 | H33: 7045.45 | I33: 1127.27 | J33: =SUM(G33:I33) -> 8508.72 | K33: 8508.72 | L33: =+J33-K33 -> 0 | M33: MXN | P33: 0 | Q33: 336 | S33: 3095.45 | T33: 0 | U33: 0 | V33: 0 | W33: 3950 | X33: 0 | Y33: 0 | Z33: 0 | AA33: 0 | AB33: =+SUM(S33:AA33)-H33 -> 0
B34: 2-002434 | C34: CGL25012532 | D34: 45706 | E34: C0002 | F34: NAPS-GUANAJUATO CAM | G34: 336 | H34: 14090.89 | I34: 2254.54 | J34: =SUM(G34:I34) -> 16681.43 | K34: 16681.43 | L34: =+J34-K34 -> 0 | M34: MXN | P34: 0 | Q34: 336 | S34: 6190.89 | T34: 0 | U34: 0 | V34: 0 | W34: 7900 | X34: 0 | Y34: 0 | Z34: 0 | AA34: 0 | AB34: =+SUM(S34:AA34)-H34 -> 0
B35: 1-002435 | C35: CGL25012538 | D35: 45706 | E35: C0001 | F35: ARMOR MEXICO IMAGING SUPPLIES | G35: 0 | H35: 16244.3 | I35: 2599.09 | J35: =SUM(G35:I35) -> 18843.39 | K35: 0 | L35: =+J35-K35 -> 18843.39 | M35: MXN | P35: 0 | Q35: 0 | S35: 8220.48 | T35: 0 | U35: 3373.82 | V35: 0 | W35: 2100 | X35: 0 | Y35: 0 | Z35: 2550 | AA35: 0 | AB35: =+SUM(S35:AA35)-H35 -> 0
B36: 1-002438 | C36: CGL24112357 | D36: 45707 | E36: C0012 | F36: MEGALUMINIO SERVICIOS | G36: 359364 | H36: 94500 | I36: 15120 | J36: =SUM(G36:I36) -> 468984 | K36: 468984 | L36: =+J36-K36 -> 0 | M36: MXN | P36: 0 | Q36: 359364 | S36: 7500 | T36: 0 | U36: 24000 | V36: 0 | W36: 63000 | X36: 0 | Y36: 0 | Z36: 0 | AA36: 0 | AB36: =+SUM(S36:AA36)-H36 -> 0
... B43: 1-002445 | C43: CGL25012540 | D43: 45707 | E43: C0084 | F43: JOINT PRODUCTION TECTRAN | G43: 0 | H43: 25000 | I43: 4000 | J43: =SUM(G43:I43) -> 29000 | K43: 29000 | L43: =+J43-K43 -> 0 | M43: MXN | P43: 0 | Q43: 0 | S43: 0 | T43: 0 | U43: 0 | V43: 0 | W43: 25000 | X43: 0 | Y43: 0 | Z43: 0 | AA43: 0 | AB43: =+SUM(S43:AA43)-H43 -> 0
B44: 2-002446 | C44: CGL25012536 | D44: 45708 | E44: C0024 | F44: SELLOS Y RETENES DE SAN LUIS | G44: 183058 | H44: 10275.6 | I44: 1644.1 | J44: =SUM(G44:I44) -> 194977.7 | K44: 187725.4 | L44: =+J44-K44 -> 7252.3 | M44: MXN | P44: 0 | Q44: 183058 | S44: =4110.24+6165.36 -> 10275.6 | T44: 0 | U44: 0 | V44: 0 | W44: 0 | X44: 0 | Y44: 0 | Z44: 0 | AA44: 0 | AB44: =+SUM(S44:AA44)-H44 -> 0
B45: 1-002447 | C45: CGL25012485 | D45: 45708 | E45: C0004 | F45: NAPS-GUANAJUATO AMERICAN BOA | G45: 781 | H45: 87882.04 | I45: 14061.13 | J45: =SUM(G45:I45) -> 102724.17 | K45: 102759.32 | L45: =+J45-K45 -> -35.15 | M45: MXN | P45: 0 | Q45: 781 | S45: 6182.04 | T45: 0 | U45: 25000 | V45: 0 | W45: 56700 | X45: 0 | Y45: 0 | Z45: 0 | AA45: 0 | AB45: =+SUM(S45:AA45)-H45 -> 0
B46: 2-002448 | C46: CGL24122389 | D46: 45708 | E46: C0002 | F46: NAPS-GUANAJUATO CAM | G46: 29189 | H46: 4713.54 | I46: 754.17 | J46: =SUM(G46:I46) -> 34656.71 | K46: 34656.71 | L46: =+J46-K46 -> 0 | M46: MXN | P46: 0 | Q46: 29189 | S46: 4113.54 | T46: 0 | U46: 0 | V46: 0 | W46: 0 | X46: 0 | Y46: 600 | Z46: 0 | AA46: 0 | AB46: =+SUM(S46:AA46)-H46 -> 0
...

Sheet FEB USD 
G1: INFORMACION EN USD | N1: INFORMACION EN MXN
A2: SERIE | B2: FACTURA | C2: TRAFICO | D2: FECHA | E2: CLIENTE | F2: CLIENTENOMBRE | G2: COMPROBADOS | H2: COMPLEMENTARIOS | I2: IVA | J2: SUBTOTAL | K2: ANTICIPO | L2: TOTAL | M2: TIPOCAMBIO | N2: COMPLEMENTARIOS | O2: IVA | P2: SUBTOTAL | Q2: ANTICIPO | R2: TOTAL | U2: SERVICIO LOGISTICO | V2: REVALIDACION GUIA | W2: LIBERACION DE DOCUMENTOS | X2: HONORARIOS | Y2: GASTOS EN DESTINO | Z2: CUOTA | AB2: SERVICIO LOGISTICO | AC2: REVALIDACION GUIA | AD2: LIBERACION DE DOCUMENTOS | AE2: HONORARIOS | AF2: GASTOS EN DESTINO | AG2: CUOTA
B3: 1-002398 | C3: CGL25012513 | D3: 45694 | E3: C0004 | F3: NAPS-GUANAJUATO AMERICAN BOA | G3: 0 | H3: 295 | I3: 47.2 | J3: =SUM(G3:I3) -> 342.2 | K3: 342.2 | L3: =J3-K3 -> 0 | M3: 20.6363 | N3: =H3*M3 -> 6087.7085 | O3: =I3*M3 -> 974.03336 | P3: =J3*M3 -> 7061.7419 | Q3: =M3*K3 -> 7061.7419 | R3: =L3*M3 -> 0 | V3: 295 | AB3: =U3*M3 -> 0 | AC3: =+V3*M3 -> 6087.7085 | AD3: =+M3*W3 -> 0 | AE3: =+X3*M3 -> 0 | AF3: =+Y3*M3 -> 0 | AG3: =+Z3*M3 -> 0
B4: 1-002400 | C4: CGL24122386 | D4: 45694 | E4: C0085 | F4: HM ULUSLARARASI PROJE TASIMACILIGI A.S | G4: 0 | H4: 75 | I4: 0 | J4: =SUM(G4:I4) -> 75 | K4: 0 | L4: =J4-K4 -> 75 | M4: 20.6363 | N4: =H4*M4 -> 1547.7225 | O4: =I4*M4 -> 0 | P4: =J4*M4 -> 1547.7225 | Q4: =M4*K4 -> 0 | R4: =L4*M4 -> 1547.7225 | V4: 75 | AB4: =U4*M4 -> 0 | AC4: =+V4*M4 -> 1547.7225 | AD4: =+M4*W4 -> 0 | AE4: =+X4*M4 -> 0 | AF4: =+Y4*M4 -> 0 | AG4: =+Z4*M4 -> 0
B5: 1-002421 | C5: CGL24122386 | D5: 45701 | E5: C0086 | F5: GOMSA INTEGRADORA | G5: 0 | H5: 245 | I5: 39.2 | J5: =SUM(G5:I5) -> 284.2 | K5: 284.2 | L5: =J5-K5 -> 0 | M5: 20.4917 | N5: =H5*M5 -> 5020.4665 | O5: =I5*M5 -> 803.27464 | P5: =J5*M5 -> 5823.7411 | Q5: =M5*K5 -> 5823.7411 | R5: =L5*M5 -> 0 | Y5: 245 | AB5: =U5*M5 -> 0 | AC5: =+V5*M5 -> 0 | AD5: =+M5*W5 -> 0 | AE5: =+X5*M5 -> 0 | AF5: =+Y5*M5 -> 5020.4665 | AG5: =+Z5*M5 -> 0
B6: 1-002422 | C6: CGL24122386 | D6: 45701 | E6: C0086 | F6: GOMSA INTEGRADORA | G6: 0 | H6: 145 | I6: 0 | J6: =SUM(G6:I6) -> 145 | K6: 145 | L6: =J6-K6 -> 0 | M6: 20.4917 | N6: =H6*M6 -> 2971.2965 | O6: =I6*M6 -> 0 | P6: =J6*M6 -> 2971.2965 | Q6: =M6*K6 -> 2971.2965 | R6: =L6*M6 -> 0 | Y6: 70 | Z6: 75 | AB6: =U6*M6 -> 0 | AC6: =+V6*M6 -> 0 | AD6: =+M6*W6 -> 0 | AE6: =+X6*M6 -> 0 | AF6: =+Y6*M6 -> 1434.419 | AG6: =+Z6*M6 -> 1536.8775
B7: 1-002426 | C7: CGL25012490 | D7: 45701 | E7: C0091 | F7: INNOVATIVE PORTING SL | G7: 0 | H7: 235 | I7: 0 | J7: =SUM(G7:I7) -> 235 | K7: 235 | L7: =J7-K7 -> 0 | M7: 20.4917 | N7: =H7*M7 -> 4815.5495 | O7: =I7*M7 -> 0 | P7: =J7*M7 -> 4815.5495 | Q7: =M7*K7 -> 4815.5495 | R7: =L7*M7 -> 0 | W7: 235 | AB7: =U7*M7 -> 0 | AC7: =+V7*M7 -> 0 | AD7: =+M7*W7 -> 4815.5495 | AE7: =+X7*M7 -> 0 | AF7: =+Y7*M7 -> 0 | AG7: =+Z7*M7 -> 0
B8: 1-002436 | C8: CGL25012490 | D8: 45707 | E8: C0093 | F8: DESCAFEINADORES MEXICANOS | G8: 0 | H8: 105 | I8: 0 | J8: =SUM(G8:I8) -> 105 | K8: 105 | L8: =J8-K8 -> 0 | M8: 20.2617 | N8: =H8*M8 -> 2127.4785 | O8: =I8*M8 -> 0 | P8: =J8*M8 -> 2127.4785 | Q8: =M8*K8 -> 2127.4785 | R8: =L8*M8 -> 0 | Y8: 105 | AB8: =U8*M8 -> 0 | AC8: =+V8*M8 -> 0 | AD8: =+M8*W8 -> 0 | AE8: =+X8*M8 -> 0 | AF8: =+Y8*M8 -> 2127.4785 | AG8: =+Z8*M8 -> 0
B9: 1-002437 | C9: CGL25012490 | D9: 45707 | E9: C0093 | F9: DESCAFEINADORES MEXICANOS | G9: 0 | H9: 50 | I9: 8 | J9: =SUM(G9:I9) -> 58 | K9: 58 | L9: =J9-K9 -> 0 | M9: 20.2617 | N9: =H9*M9 -> 1013.085 | O9: =I9*M9 -> 162.0936 | P9: =J9*M9 -> 1175.1786 | Q9: =M9*K9 -> 1175.1786 | R9: =L9*M9 -> 0 | Y9: 50 | AB9: =U9*M9 -> 0 | AC9: =+V9*M9 -> 0 | AD9: =+M9*W9 -> 0 | AE9: =+X9*M9 -> 0 | AF9: =+Y9*M9 -> 1013.085 | AG9: =+Z9*M9 -> 0
B10: 1-002454 | C10: CGL25012438 | D10: 45712 | E10: C0079 | F10: CORE GLOBAL TRANSPORT | G10: 0 | H10: 1725 | I10: 0 | J10: =SUM(G10:I10) -> 1725 | K10: 0 | L10: =J10-K10 -> 1725 | M10: 20.3448 | N10: =H10*M10 -> 35094.78 | O10: =I10*M10 -> 0 | P10: =J10*M10 -> 35094.78 | Q10: =M10*K10 -> 0 | R10: =L10*M10 -> 35094.78 | U10: 1725 | AB10: =U10*M10 -> 35094.78 | AC10: =+V10*M10 -> 0 | AD10: =+M10*W10 -> 0 | AE10: =+X10*M10 -> 0 | AF10: =+Y10*M10 -> 0 | AG10: =+Z10*M10 -> 0
B11: 2-002463 | C11: CGL25012519 | D11: 45714 | E11: C0084 | F11: JOINT PRODUCTION TECTRAN | G11: 0 | H11: 6125 | I11: 0 | J11: =SUM(G11:I11) -> 6125 | K11: 0 | L11: =J11-K11 -> 6125 | M11: 20.4683 | N11: =H11*M11 -> 125368.34 | O11: =I11*M11 -> 0 | P11: =J11*M11 -> 125368.34 | Q11: =M11*K11 -> 0 | R11: =L11*M11 -> 125368.34 | U11: 6125 | AB11: =U11*M11 -> 125368.34 | AC11: =+V11*M11 -> 0 | AD11: =+M11*W11 -> 0 | AE11: =+X11*M11 -> 0 | AF11: =+Y11*M11 -> 0 | AG11: =+Z11*M11 -> 0
B12: 1-002472 | C12: CGL25012499 | D12: 45715 | E12: C0086 | F12: GOMSA INTEGRADORA | G12: 0 | H12: 245 | I12: 39.2 | J12: =SUM(G12:I12) -> 284.2 | K12: 284.2 | L12: =J12-K12 -> 0 | M12: 20.4277 | N12: =H12*M12 -> 5004.7865 | O12: =I12*M12 -> 800.76584 | P12: =J12*M12 -> 5805.5523 | Q12: =M12*K12 -> 5805.5523 | R12: =L12*M12 -> 0 | Y12: 245 | AB12: =U12*M12 -> 0 | AC12: =+V12*M12 -> 0 | AD12: =+M12*W12 -> 0 | AE12: =+X12*M12 -> 0 | AF12: =+Y12*M12 -> 5004.7865 | AG12: =+Z12*M12 -> 0
B13: 1-002473 | C13: CGL25012499 | D13: 45715 | E13: C0086 | F13: GOMSA INTEGRADORA | G13: 0 | H13: 125 | I13: 0 | J13: =SUM(G13:I13) -> 125 | K13: 125 | L13: =J13-K13 -> 0 | M13: 20.4277 | N13: =H13*M13 -> 2553.4625 | O13: =I13*M13 -> 0 | P13: =J13*M13 -> 2553.4625 | Q13: =M13*K13 -> 2553.4625 | R13: =L13*M13 -> 0 | V13: 125 | AB13: =U13*M13 -> 0 | AC13: =+V13*M13 -> 2553.4625 | AD13: =+M13*W13 -> 0 | AE13: =+X13*M13 -> 0 | AF13: =+Y13*M13 -> 0 | AG13: =+Z13*M13 -> 0
J14: =SUM(G14:I14) -> 0 | L14: =J14-K14 -> 0 | N14: =H14*M14 -> 0 | O14: =I14*M14 -> 0 | P14: =J14*M14 -> 0 | Q14: =M14*K14 -> 0 | R14: =L14*M14 -> 0 | AB14: =U14*M14 -> 0 | AC14: =+V14*M14 -> 0 | AD14: =+M14*W14 -> 0 | AE14: =+X14*M14 -> 0 | AF14: =+Y14*M14 -> 0 | AG14: =+Z14*M14 -> 0
J15: =SUM(G15:I15) -> 0 | L15: =J15-K15 -> 0 | N15: =H15*M15 -> 0 | O15: =I15*M15 -> 0 | P15: =J15*M15 -> 0 | Q15: =M15*K15 -> 0 | R15: =L15*M15 -> 0 | AB15: =U15*M15 -> 0 | AC15: =+V15*M15 -> 0 | AD15: =+M15*W15 -> 0 | AE15: =+X15*M15 -> 0 | AF15: =+Y15*M15 -> 0 | AG15: =+Z15*M15 -> 0
J16: =SUM(G16:I16) -> 0 | L16: =J16-K16 -> 0 | N16: =H16*M16 -> 0 | O16: =I16*M16 -> 0 | P16: =J16*M16 -> 0 | Q16: =M16*K16 -> 0 | R16: =L16*M16 -> 0 | AB16: =U16*M16 -> 0 | AC16: =+V16*M16 -> 0 | AD16: =+M16*W16 -> 0 | AE16: =+X16*M16 -> 0 | AF16: =+Y16*M16 -> 0 | AG16: =+Z16*M16 -> 0
J17: =SUM(G17:I17) -> 0 | L17: =J17-K17 -> 0 | N17: =H17*M17 -> 0 | O17: =I17*M17 -> 0 | P17: =J17*M17 -> 0 | Q17: =M17*K17 -> 0 | R17: =L17*M17 -> 0 | AB17: =U17*M17 -> 0 | AC17: =+V17*M17 -> 0 | AD17: =+M17*W17 -> 0 | AE17: =+X17*M17 -> 0 | AF17: =+Y17*M17 -> 0 | AG17: =+Z17*M17 -> 0
J18: =SUM(G18:I18) -> 0 | L18: =J18-K18 -> 0 | N18: =H18*M18 -> 0 | O18: =I18*M18 -> 0 | P18: =J18*M18 -> 0 | Q18: =M18*K18 -> 0 | R18: =L18*M18 -> 0 | AB18: =U18*M18 -> 0 | AC18: =+V18*M18 -> 0 | AD18: =+M18*W18 -> 0 | AE18: =+X18*M18 -> 0 | AF18: =+Y18*M18 -> 0 | AG18: =+Z18*M18 -> 0
G19: =+SUM(G3:G18) -> 0 | H19: =+SUM(H3:H18) -> 9370 | I19: =+SUM(I3:I18) -> 133.6 | J19: =+SUM(J3:J18) -> 9503.6 | K19: =+SUM(K3:K18) -> 1578.6 | L19: =+SUM(L3:L18) -> 7925 | N19: =+SUM(N3:N18) -> 191604.67 | O19: =+SUM(O3:O18) -> 2740.1674 | P19: =+SUM(P3:P18) -> 194344.84 | Q19: =+SUM(Q3:Q18) -> 32334.001 | R19: =+SUM(R3:R18) -> 162010.84 | U19: =+SUM(U3:U18) -> 7850 | V19: =+SUM(V3:V18) -> 495 | W19: =+SUM(W3:W18) -> 235 | X19: =+SUM(X3:X18) -> 0 | Y19: =+SUM(Y3:Y18) -> 715 | Z19: =+SUM(Z3:Z18) -> 75 | AB19: =+SUM(AB3:AB18) -> 160463.12 | AC19: =+SUM(AC3:AC18) -> 10188.894 | AD19: =+SUM(AD3:AD18) -> 4815.5495 | AE19: =+SUM(AE3:AE18) -> 0 | AF19: =+SUM(AF3:AF18) -> 14600.236 | AG19: =+SUM(AG3:AG18) -> 1536.8775
Z20: =+SUM(T19:Z19) -> 9370 | AG20: =+SUM(AB19:AG19) -> 191604.67
Z21: =+Z20-H19 -> 0 | AG21: =+AG20-N19 -> 0
N22: =+N3+N5+N9+N12 -> 17126.046 | O22: 0.16
N23: =+N4+N6+N7+N8+N10+N11+N13 -> 174478.63 | O23: 0

Sheet MAR MXN
A1: SERIE | B1: FACTURA | C1: TRAFICO | D1: FECHA | E1: CLIENTE | F1: CLIENTE NOMBRE | G1: COMPROBADOS | H1: COMPLEMENTARIOS | I1: IVA | J1: SUBTOTAL | K1: ANTICIPO | L1: TOTAL | M1: MONEDA | P1: DOCUMENTACION, ALMACENAJES Y MANIOBRAS ( TER) | Q1: IMPUESTOS ADUANALES (TER) | S1: HONORARIOS | T1: REVALIDACION GUIA / BOL | U1: MANIOBRAS | V1: ALMACENAJES | W1: SERVICIOS LOGISTICOS | X1: CONSOLIDACION DE ENTRADAS | Y1: RECONOCIMIENTO ADUANERO | Z1: GASTOS EN ORIGEN | AA1: CERTIFICADO DE ORIGEN | AB1: SERVICIOS EXTRAORDINARIO | AC1: SERVICIOS COMPLEMENTARIOS | AD1: SERVICIO DE MENSAJERIA | AE1: LIBRACION DE DOCUMENTOS | AF1: GASTOS EN DESTINO | AJ1: MXN | AK1: USD | AL1: TOTAL | AM1: PORCENTAJE
A2: 1000 | B2: 1-002480 | C2: CGL25022585 | D2: 45720 | E2: C0004 | F2: NAPS-GUANAJUATO AMERICAN BOA | G2: 781 | H2: 27923.01 | I2: 4467.68 | J2: =SUM(G2:I2) -> 33171.69 | K2: 33455.25 | L2: =+J2-K2 -> -283.56 | M2: MXN | P2: 0 | Q2: 781 | S2: 6128.31 | T2: 5197.2 | U2: 15000 | V2: 0 | W2: 0 | X2: 0 | Y2: 0 | Z2: 0 | AA2: 0 | AB2: 0 | AC2: 0 | AD2: 0 | AE2: 0 | AF2: 1597.5 | AG2: =+SUM(S2:AF2)-H2 -> 0 | AI2: HONORARIOS | AJ2: =+S100 -> 396873.24 | AL2: =SUM(AJ2:AK2) -> 396873.24 | AM2: =+AL2/AL17 -> 0.13022685
A3: 2000 | B3: 2-002483 | C3: CGL25022594 | D3: 45721 | E3: C0002 | F3: NAPS-GUANAJUATO CAM | G3: 336 | H3: 14040.49 | I3: 2246.48 | J3: =SUM(G3:I3) -> 16622.97 | K3: 16622.97 | L3: =+J3-K3 -> 0 | M3: MXN | P3: 0 | Q3: 336 | S3: 6140.49 | T3: 0 | U3: 0 | V3: 0 | W3: 7900 | X3: 0 | Y3: 0 | Z3: 0 | AA3: 0 | AB3: 0 | AC3: 0 | AD3: 0 | AE3: 0 | AF3: 0 | AG3: =+SUM(S3:AF3)-H3 -> 0 | AI3: REVALIDACION GUIA / BOL | AJ3: =+T100 -> 17053.96 | AK3: =+'MAR USD '!AC19 -> 5045.5992 | AL3: =SUM(AJ3:AK3) -> 22099.559 | AM3: =+AL3/AL17 -> 0.0072515747
A4: 2000 | B4: 2-002484 | C4: CGL25022593 | D4: 45721 | E4: C0002 | F4: NAPS-GUANAJUATO CAM | G4: 336 | H4: 14040.49 | I4: 2246.48 | J4: =SUM(G4:I4) -> 16622.97 | K4: 16622.97 | L4: =+J4-K4 -> 0 | M4: MXN | P4: 0 | Q4: 336 | S4: 6140.49 | T4: 0 | U4: 0 | V4: 0 | W4: 7900 | X4: 0 | Y4: 0 | Z4: 0 | AA4: 0 | AB4: 0 | AC4: 0 | AD4: 0 | AE4: 0 | AF4: 0 | AG4: =+SUM(S4:AF4)-H4 -> 0 | AI4: MANIOBRAS | AJ4: =+U100 -> 558468.45 | AK4: =+'MAR USD '!AD19 -> 14280.21 | AL4: =SUM(AJ4:AK4) -> 572748.66 | AM4: =+AL4/AL17 -> 0.18793722
A5: 1000 | B5: 1-002485 | C5: CGL25022566 | D5: 45722 | E5: C0001 | F5: ARMOR MEXICO IMAGING SUPPLIES | G5: 0 | H5: 73861.99 | I5: 11817.92 | J5: =SUM(G5:I5) -> 85679.91 | K5: 0 | L5: =+J5-K5 -> 85679.91 | M5: MXN | P5: 0 | Q5: 0 | S5: 6111.99 | T5: 0 | U5: 25750 | V5: 0 | W5: 42000 | X5: 0 | Y5: 0 | Z5: 0 | AA5: 0 | AB5: 0 | AC5: 0 | AD5: 0 | AE5: 0 | AF5: 0 | AG5: =+SUM(S5:AF5)-H5 -> 0 | AI5: ALMACENAJES | AJ5: =+V100 -> 16647.13 | AK5: =+'MAR USD '!AE19 -> 157626.59 | AL5: =SUM(AJ5:AK5) -> 174273.72 | AM5: =+AL5/AL17 -> 0.057184801
A6: 2000 | B6: 2-002486 | C6: CGL25022577 | D6: 45722 | E6: C0002 | F6: NAPS-GUANAJUATO CAM | G6: 30731 | H6: 14163.85 | I6: 2266.22 | J6: =SUM(G6:I6) -> 47161.07 | K6: 47094.07 | L6: =+J6-K6 -> 67 | M6: MXN | P6: 0 | Q6: 30731 | S6: 4085.54 | T6: 0 | U6: 0 | V6: 0 | W6: 3950 | X6: 6128.31 | Y6: 0 | Z6: 0 | AA6: 0 | AB6: 0 | AC6: 0 | AD6: 0 | AE6: 0 | AF6: 0 | AG6: =+SUM(S6:AF6)-H6 -> 0 | AI6: SERVICIOS LOGISTICOS | AJ6: =+W100 -> 1298164 | AK6: =+'MAR USD '!AB19 -> 402610.74 | AL6: =SUM(AJ6:AK6) -> 1700774.7 | AM6: =+AL6/AL17 -> 0.55807878
A7: 2000 | B7: 2-002487 | C7: CGL25022599 | D7: 45722 | E7: C0024 | F7: SELLOS Y RETENES DE SAN LUIS | G7: 40553 | H7: 7700.77 | I7: 1232.13 | J7: =SUM(G7:I7) -> 49485.9 | K7: 49485.9 | L7: =+J7-K7 -> 0 | M7: MXN | P7: 0 | Q7: 40553 | S7: =6165.35+1535.42 -> 7700.77 | T7: 0 | U7: 0 | V7: 0 | W7: 0 | X7: 0 | Y7: 0 | Z7: 0 | AA7: 0 | AB7: 0 | AC7: 0 | AD7: 0 | AE7: 0 | AF7: 0 | AG7: =+SUM(S7:AF7)-H7 -> 0 | AI7: CONSOLIDACION DE ENTRADAS | AJ7: =+X100 -> 38443.89 | AL7: =SUM(AJ7:AK7) -> 38443.89 | AM7: =+AL7/AL17 -> 0.012614674
A8: 1000 | B8: 1-002488 | C8: CGL25022628 | D8: 45722 | E8: C0006 | F8: CLEVELAND DIE QUERETARO | G8: 14746 | H8: 34700 | I8: 5552 | J8: =SUM(G8:I8) -> 54998 | K8: 54998 | L8: =+J8-K8 -> 0 | M8: MXN | P8: 0 | Q8: 14746 | S8: 6500 | T8: 0 | U8: 24000 | V8: 0 | W8: 4200 | X8: 0 | Y8: 0 | Z8: 0 | AA8: 0 | AB8: 0 | AC8: 0 | AD8: 0 | AE8: 0 | AF8: 0 | AG8: =+SUM(S8:AF8)-H8 -> 0 | AI8: RECONOCIMIENTO ADUANERO | AJ8: =+Y100 -> 12000 | AL8: =SUM(AJ8:AK8) -> 12000 | AM8: =+AL8/AL17 -> 0.0039375852
A9: 1000 | B9: 1-002490 | C9: CGL25032636 | D9: 45726 | E9: C0001 | F9: ARMOR MEXICO IMAGING SUPPLIES | G9: 0 | H9: 11340.08 | I9: 1814.42 | J9: =SUM(G9:I9) -> 13154.5 | K9: 0 | L9: =+J9-K9 -> 13154.5 | M9: MXN | P9: 0 | Q9: 0 | S9: 4092.8 | T9: 0 | U9: 3569.8 | V9: 1177.48 | W9: 2500 | X9: 0 | Y9: 0 | Z9: 0 | AA9: 0 | AB9: 0 | AC9: 0 | AD9: 0 | AE9: 0 | AF9: 0 | AG9: =+SUM(S9:AF9)-H9 -> 0 | AI9: GASTOS EN ORIGEN | AJ9: =+Z100 -> 7200 | AL9: =SUM(AJ9:AK9) -> 7200 | AM9: =+AL9/AL17 -> 0.0023625511
A10: 1000 | B10: 1-002491 | C10: CGL25032675 | D10: 45728 | E10: C0001 | F10: ARMOR MEXICO IMAGING SUPPLIES | G10: 0 | H10: 3540 | I10: 566.4 | J10: =SUM(G10:I10) -> 4106.4 | K10: 0 | L10: =+J10-K10 -> 4106.4 | M10: MXN | P10: 0 | Q10: 0 | S10: 0 | T10: 0 | U10: 0 | V10: 0 | W10: 0 | X10: 0 | Y10: 0 | Z10: 0 | AA10: 3540 | AB10: 0 | AC10: 0 | AD10: 0 | AE10: 0 | AF10: 0 | AG10: =+SUM(S10:AF10)-H10 -> 0 | AI10: CERTIFICADO DE ORIGEN | AJ10: =+AA100 -> 10620 | AL10: =SUM(AJ10:AK10) -> 10620 | AM10: =+AL10/AL17 -> 0.0034847629
A11: 2000 | B11: 2-002492 | C11: CGL25012529 | D11: 45729 | E11: C0002 | F11: NAPS-GUANAJUATO CAM | G11: 6808 | H11: 4101.6 | I11: 656.26 | J11: =SUM(G11:I11) -> 11565.86 | K11: 11565.86 | L11: =+J11-K11 -> 0 | M11: MXN | P11: 0 | Q11: 6808 | S11: 4101.6 | T11: 0 | U11: 0 | V11: 0 | W11: 0 | X11: 0 | Y11: 0 | Z11: 0 | AA11: 0 | AB11: 0 | AC11: 0 | AD11: 0 | AE11: 0 | AF11: 0 | AG11: =+SUM(S11:AF11)-H11 -> 0 | AI11: SERVICIOS EXTRAORDINARIO | AJ11: =+AB100 -> 8440 | AL11: =SUM(AJ11:AK11) -> 8440 | AM11: =+AL11/AL17 -> 0.0027694349
A12: 2000 | B12: 2-002493 | C12: CGL25022626 | D12: 45729 | E12: C0002 | F12: NAPS-GUANAJUATO CAM | G12: 336 | H12: 14155.54 | I12: 2264.89 | J12: =SUM(G12:I12) -> 16756.43 | K12: 16756.43 | L12: =+J12-K12 -> 0 | M12: MXN | P12: 0 | Q12: 336 | S12: 6255.54 | T12: 0 | U12: 0 | V12: 0 | W12: 7900 | X12: 0 | Y12: 0 | Z12: 0 | AA12: 0 | AB12: 0 | AC12: 0 | AD12: 0 | AE12: 0 | AF12: 0 | AG12: =+SUM(S12:AF12)-H12 -> 0 | AI12: SERVICIOS COMPLEMENTARIOS | AJ12: =+AC100 -> 6500 | AL12: =SUM(AJ12:AK12) -> 6500 | AM12: =+AL12/AL17 -> 0.0021328586
A13: 2000 | B13: 2-002494 | C13: CGL25032639 | D13: 45729 | E13: C0002 | F13: NAPS-GUANAJUATO CAM | G13: 781 | H13: 8120.36 | I13: 1299.26 | J13: =SUM(G13:I13) -> 10200.62 | K13: 10200.62 | L13: =+J13-K13 -> 0 | M13: MXN | P13: 0 | Q13: 781 | S13: 4170.36 | T13: 0 | U13: 0 | V13: 0 | W13: 3950 | X13: 0 | Y13: 0 | Z13: 0 | AA13: 0 | AB13: 0 | AC13: 0 | AD13: 0 | AE13: 0 | AF13: 0 | AG13: =+SUM(S13:AF13)-H13 -> 0 | AI13: SERVICIO DE MENSAJERIA | AJ13: =+AD100 -> 1000 | AL13: =SUM(AJ13:AK13) -> 1000 | AM13: =+AL13/AL17 -> 0.0003281321
A14: 2000 | B14: 2-002495 | C14: CGL25032640 | D14: 45729 | E14: C0002 | F14: NAPS-GUANAJUATO CAM | G14: 781 | H14: 8120.36 | I14: 1299.26 | J14: =SUM(G14:I14) -> 10200.62 | K14: 10200.62 | L14: =+J14-K14 -> 0 | M14: MXN | P14: 0 | Q14: 781 | S14: 4170.36 | T14: 0 | U14: 0 | V14: 0 | W14: 3950 | X14: 0 | Y14: 0 | Z14: 0 | AA14: 0 | AB14: 0 | AC14: 0 | AD14: 0 | AE14: 0 | AF14: 0 | AG14: =+SUM(S14:AF14)-H14 -> 0 | AI14: LIBRACION DE DOCUMENTOS | AJ14: =+AE100 -> 3195 | AL14: =SUM(AJ14:AK14) -> 3195 | AM14: =+AL14/AL17 -> 0.0010483821
A15: 2000 | B15: 2-002496 | C15: CGL25032641 | D15: 45729 | E15: C0002 | F15: NAPS-GUANAJUATO CAM | G15: 781 | H15: 8120.36 | I15: 1299.26 | J15: =SUM(G15:I15) -> 10200.62 | K15: 10200.62 | L15: =+J15-K15 -> 0 | M15: MXN | P15: 0 | Q15: 781 | S15: 4170.36 | T15: 0 | U15: 0 | V15: 0 | W15: 3950 | X15: 0 | Y15: 0 | Z15: 0 | AA15: 0 | AB15: 0 | AC15: 0 | AD15: 0 | AE15: 0 | AF15: 0 | AG15: =+SUM(S15:AF15)-H15 -> 0 | AI15: GASTOS EN DESTINO | AJ15: =+AF100 -> 43554.1 | AK15: =+'MAR USD '!AF19 -> 49830.213 | AL15: =SUM(AJ15:AK15) -> 93384.313 | AM15: =+AL15/AL17 -> 0.03064239
A16: 2000 | B16: 2-002497 | C16: CGL25022627 | D16: 45729 | E16: C0002 | F16: NAPS-GUANAJUATO CAM | G16: 336 | H16: 14155.54 | I16: 2264.89 | J16: =SUM(G16:I16) -> 16756.43 | K16: 16756.43 | L16: =+J16-K16 -> 0 | M16: MXN | P16: 0 | Q16: 336 | S16: 6255.54 | T16: 0 | U16: 0 | V16: 0 | W16: 7900 | X16: 0 | Y16: 0 | Z16: 0 | AA16: 0 | AB16: 0 | AC16: 0 | AD16: 0 | AE16: 0 | AF16: 0 | AG16: =+SUM(S16:AF16)-H16 -> 0
